Workbook

Sheet README
A1: pysystemtrade — Excel Learning Model
A3: Purpose
A4: This workbook reproduces the core mechanics of Rob Carver's 'Chapter 15' systematic
A5: futures system as implemented in pysystemtrade. Every cell is a live formula so you can
A6: change any input (price, parameter, weight) and watch the position update.
A8: Sheet map
A9: 1. Inputs — capital, vol target, contract specs, all tunable parameters.
A10: 2. Prices — 180 days of synthetic Gold prices + daily returns + blended vol.
A11: 3. Rules — EWMAC(16/64 & 64/256), Carry, Breakout(40) forecasts — raw, scaled, capped.
A12: 4. Combine — weighted forecasts, FDM, final combined forecast.
A13: 5. Position — daily cash vol target → instrument vol → vol scalar → position.
A14: 6. Portfolio — 6 instruments, instrument weights, IDM, portfolio risk check.
... A55: portfolio risk, and weak views on quiet things without leaving money on the table.

Sheet Inputs
A1: Inputs — every parameter that drives the model
A3: Capital & risk
A4: Notional trading capital | B4: 1000000 | D4: Dollars of capital the system sizes against
A5: Annual % volatility target | B5: 0.2 | D5: Annualised stdev of P&L as % of capital
A6: Business days per year | B6: 256 | D6: Used for annual↔daily vol
A7: Average absolute forecast | B7: 10 | D7: Forecasts are scaled so |avg| ≈ 10
A8: Forecast cap | B8: 20 | D8: Forecasts clipped to ±20
A10: Gold contract specs
A11: Point size ($ per 1.00 move) | B11: 100
A12: FX rate (local → base) | B12: 1
A13: Multiplier (holding cost etc) | B13: 1
A15: Volatility estimate parameters
A16: Short-vol EWM span (days) | B16: 35
A17: Blend weight on short vol | B17: 0.7
A18: Long-vol lookback (bars) | B18: 180
A20: Rule parameters (chapter15 defaults)
A21: EWMAC slow: Lfast | B21: 64
A22: EWMAC slow: Lslow | B22: 256
A23: EWMAC med: Lfast | B23: 16
A24: EWMAC med: Lslow | B24: 64
A25: Breakout lookback | B25: 40
A26: Carry smooth days | B26: 90
A28: Forecast scalars (futuresconfig.yaml)
A29: Scalar: EWMAC 64/256 | B29: 1.87
A30: Scalar: EWMAC 16/64 | B30: 3.75
A31: Scalar: Carry | B31: 30
A32: Scalar: Breakout 40 | B32: 0.7
A34: Forecast weights (sum to 1)
A35: Weight: EWMAC 64/256 | B35: 0.25
A36: Weight: EWMAC 16/64 | B36: 0.25
A37: Weight: Carry | B37: 0.35
A38: Weight: Breakout 40 | B38: 0.15
A39: SUM check | B39: =SUM(B35:B38) -> 1
A40: Forecast Diversification Multiplier (FDM) | B40: 1.31

Sheet Prices
A1: Prices — Gold daily series + daily % vol (blended short+long)
A3: Day | B3: Date | C3: Price | D3: Daily return | E3: Short EWM vol | F3: Long-run vol | G3: Blended daily vol
A4: 1 | B4: 45870 | C4: 2400
A5: 2 | B5: 45873 | C5: 2399.42 | D5: =C5/C4-1 -> -0.00024166667
A6: 3 | B6: 45874 | C6: 2398.15 | D6: =C6/C5-1 -> -0.00052929458
A7: 4 | B7: 45875 | C7: 2398.36 | D7: =C7/C6-1 -> 8.75675e-05
A8: 5 | B8: 45876 | C8: 2418.07 | D8: =C8/C7-1 -> 0.0082181157
A9: 6 | B9: 45877 | C9: 2417.89 | D9: =C9/C8-1 -> -7.4439532e-05
A10: 7 | B10: 45880 | C10: 2384.59 | D10: =C10/C9-1 -> -0.013772339
A11: 8 | B11: 45881 | C11: 2395.37 | D11: =C11/C10-1 -> 0.0045206933
A12: 9 | B12: 45882 | C12: 2391.85 | D12: =C12/C11-1 -> -0.0014695016
A13: 10 | B13: 45883 | C13: 2389.53 | D13: =C13/C12-1 -> -0.00096996049
A14: 11 | B14: 45884 | C14: 2395.16 | D14: =C14/C13-1 -> 0.0023561119 | E14: =STDEV(OFFSET(D14,-MIN(Inputs!$B$16-1,14-5),0,MIN(Inputs!$B$16,14-4+1),1)) -> 0.0054664838 | F14: =STDEV(D$5:D14) -> 0.0056401659 | G14: =Inputs!$B$17*E14+(1-Inputs!$B$17)*F14 -> 0.0055185884
A15: 12 | B15: 45887 | C15: 2403.6 | D15: =C15/C14-1 -> 0.0035237729 | E15: =STDEV(OFFSET(D15,-MIN(Inputs!$B$16-1,15-5),0,MIN(Inputs!$B$16,15-4+1),1)) -> 0.0063698478 | F15: =STDEV(D$5:D15) -> 0.0054664838 | G15: =Inputs!$B$17*E15+(1-Inputs!$B$17)*F15 -> 0.0060988386
A16: 13 | B16: 45888 | C16: 2434.45 | D16: =C16/C15-1 -> 0.012834914 | E16: =STDEV(OFFSET(D16,-MIN(Inputs!$B$16-1,16-5),0,MIN(Inputs!$B$16,16-4+1),1)) -> 0.0063643277 | F16: =STDEV(D$5:D16) -> 0.0063698478 | G16: =Inputs!$B$17*E16+(1-Inputs!$B$17)*F16 -> 0.0063659838
A17: 14 | B17: 45889 | C17: 2453.36 | D17: =C17/C16-1 -> 0.0077676683 | E17: =STDEV(OFFSET(D17,-MIN(Inputs!$B$16-1,17-5),0,MIN(Inputs!$B$16,17-4+1),1)) -> 0.0061166901 | F17: =STDEV(D$5:D17) -> 0.0063643277 | G17: =Inputs!$B$17*E17+(1-Inputs!$B$17)*F17 -> 0.0061909814
A18: 15 | B18: 45890 | C18: 2459.01 | D18: =C18/C17-1 -> 0.0023029641 | E18: =STDEV(OFFSET(D18,-MIN(Inputs!$B$16-1,18-5),0,MIN(Inputs!$B$16,18-4+1),1)) -> 0.0062401407 | F18: =STDEV(D$5:D18) -> 0.0061166901 | G18: =Inputs!$B$17*E18+(1-Inputs!$B$17)*F18 -> 0.0062031055
A19: 16 | B19: 45891 | C19: 2443.81 | D19: =C19/C18-1 -> -0.0061813494 | E19: =STDEV(OFFSET(D19,-MIN(Inputs!$B$16-1,19-5),0,MIN(Inputs!$B$16,19-4+1),1)) -> 0.0065427532 | F19: =STDEV(D$5:D19) -> 0.0062401407 | G19: =Inputs!$B$17*E19+(1-Inputs!$B$17)*F19 -> 0.0064519695
A20: 17 | B20: 45894 | C20: 2421.95 | D20: =C20/C19-1 -> -0.0089450489 | E20: =STDEV(OFFSET(D20,-MIN(Inputs!$B$16-1,20-5),0,MIN(Inputs!$B$16,20-4+1),1)) -> 0.006378688 | F20: =STDEV(D$5:D20) -> 0.0065427532 | G20: =Inputs!$B$17*E20+(1-Inputs!$B$17)*F20 -> 0.0064279076
A21: 18 | B21: 45895 | C21: 2430.82 | D21: =C21/C20-1 -> 0.0036623382 | E21: =STDEV(OFFSET(D21,-MIN(Inputs!$B$16-1,21-5),0,MIN(Inputs!$B$16,21-4+1),1)) -> 0.0069629292 | F21: =STDEV(D$5:D21) -> 0.006378688 | G21: =Inputs!$B$17*E21+(1-Inputs!$B$17)*F21 -> 0.0067876568
A22: 19 | B22: 45896 | C22: 2465.61 | D22: =C22/C21-1 -> 0.014312043 | E22: =STDEV(OFFSET(D22,-MIN(Inputs!$B$16-1,22-5),0,MIN(Inputs!$B$16,22-4+1),1)) -> 0.0067667837 | F22: =STDEV(D$5:D22) -> 0.0069629292 | G22: =Inputs!$B$17*E22+(1-Inputs!$B$17)*F22 -> 0.0068256273
A23: 20 | B23: 45897 | C23: 2469.59 | D23: =C23/C22-1 -> 0.001614205 | E23: =STDEV(OFFSET(D23,-MIN(Inputs!$B$16-1,23-5),0,MIN(Inputs!$B$16,23-4+1),1)) -> 0.0065936283 | F23: =STDEV(D$5:D23) -> 0.0067667837 | G23: =Inputs!$B$17*E23+(1-Inputs!$B$17)*F23 -> 0.0066455749
A24: 21 | B24: 45898 | C24: 2469.93 | D24: =C24/C23-1 -> 0.00013767467 | E24: =STDEV(OFFSET(D24,-MIN(Inputs!$B$16-1,24-5),0,MIN(Inputs!$B$16,24-4+1),1)) -> 0.0065208653 | F24: =STDEV(D$5:D24) -> 0.0065936283 | G24: =Inputs!$B$17*E24+(1-Inputs!$B$17)*F24 -> 0.0065426942
A25: 22 | B25: 45901 | C25: 2486.03 | D25: =C25/C24-1 -> 0.0065184034 | E25: =STDEV(OFFSET(D25,-MIN(Inputs!$B$16-1,25-5),0,MIN(Inputs!$B$16,25-4+1),1)) -> 0.0071252696 | F25: =STDEV(D$5:D25) -> 0.0065208653 | G25: =Inputs!$B$17*E25+(1-Inputs!$B$17)*F25 -> 0.0069439483
A26: 23 | B26: 45902 | C26: 2452.88 | D26: =C26/C25-1 -> -0.013334513 | E26: =STDEV(OFFSET(D26,-MIN(Inputs!$B$16-1,26-5),0,MIN(Inputs!$B$16,26-4+1),1)) -> 0.006988382 | F26: =STDEV(D$5:D26) -> 0.0071252696 | G26: =Inputs!$B$17*E26+(1-Inputs!$B$17)*F26 -> 0.0070294482
A27: 24 | B27: 45903 | C27: 2448.16 | D27: =C27/C26-1 -> -0.0019242686 | E27: =STDEV(OFFSET(D27,-MIN(Inputs!$B$16-1,27-5),0,MIN(Inputs!$B$16,27-4+1),1)) -> 0.0069171727 | F27: =STDEV(D$5:D27) -> 0.006988382 | G27: =Inputs!$B$17*E27+(1-Inputs!$B$17)*F27 -> 0.0069385355
A28: 25 | B28: 45904 | C28: 2463.1 | D28: =C28/C27-1 -> 0.0061025423 | E28: =STDEV(OFFSET(D28,-MIN(Inputs!$B$16-1,28-5),0,MIN(Inputs!$B$16,28-4+1),1)) -> 0.0069980168 | F28: =STDEV(D$5:D28) -> 0.0069171727 | G28: =Inputs!$B$17*E28+(1-Inputs!$B$17)*F28 -> 0.0069737635
A29: 26 | B29: 45905 | C29: 2487.57 | D29: =C29/C28-1 -> 0.0099346352 | E29: =STDEV(OFFSET(D29,-MIN(Inputs!$B$16-1,29-5),0,MIN(Inputs!$B$16,29-4+1),1)) -> 0.0068765047 | F29: =STDEV(D$5:D29) -> 0.0069980168 | G29: =Inputs!$B$17*E29+(1-Inputs!$B$17)*F29 -> 0.0069129583
A30: 27 | B30: 45908 | C30: 2484.57 | D30: =C30/C29-1 -> -0.0012059962 | E30: =STDEV(OFFSET(D30,-MIN(Inputs!$B$16-1,30-5),0,MIN(Inputs!$B$16,30-4+1),1)) -> 0.0067786848 | F30: =STDEV(D$5:D30) -> 0.0068765047 | G30: =Inputs!$B$17*E30+(1-Inputs!$B$17)*F30 -> 0.0068080308
A31: 28 | B31: 45909 | C31: 2496.91 | D31: =C31/C30-1 -> 0.0049666542 | E31: =STDEV(OFFSET(D31,-MIN(Inputs!$B$16-1,31-5),0,MIN(Inputs!$B$16,31-4+1),1)) -> 0.0066648462 | F31: =STDEV(D$5:D31) -> 0.0067786848 | G31: =Inputs!$B$17*E31+(1-Inputs!$B$17)*F31 -> 0.0066989978
A32: 29 | B32: 45910 | C32: 2506.1 | D32: =C32/C31-1 -> 0.0036805492 | E32: =STDEV(OFFSET(D32,-MIN(Inputs!$B$16-1,32-5),0,MIN(Inputs!$B$16,32-4+1),1)) -> 0.0066895351 | F32: =STDEV(D$5:D32) -> 0.0066648462 | G32: =Inputs!$B$17*E32+(1-Inputs!$B$17)*F32 -> 0.0066821284
A33: 30 | B33: 45911 | C33: 2528.71 | D33: =C33/C32-1 -> 0.0090219864 | E33: =STDEV(OFFSET(D33,-MIN(Inputs!$B$16-1,33-5),0,MIN(Inputs!$B$16,33-4+1),1)) -> 0.006914656 | F33: =STDEV(D$5:D33) -> 0.0066895351 | G33: =Inputs!$B$17*E33+(1-Inputs!$B$17)*F33 -> 0.0068471198
A34: 31 | B34: 45912 | C34: 2503.6 | D34: =C34/C33-1 -> -0.0099299643 | E34: =STDEV(OFFSET(D34,-MIN(Inputs!$B$16-1,34-5),0,MIN(Inputs!$B$16,34-4+1),1)) -> 0.0068685231 | F34: =STDEV(D$5:D34) -> 0.006914656 | G34: =Inputs!$B$17*E34+(1-Inputs!$B$17)*F34 -> 0.006882363
A35: 32 | B35: 45915 | C35: 2520.83 | D35: =C35/C34-1 -> 0.0068820898 | E35: =STDEV(OFFSET(D35,-MIN(Inputs!$B$16-1,35-5),0,MIN(Inputs!$B$16,35-4+1),1)) -> 0.0072947558 | F35: =STDEV(D$5:D35) -> 0.0068685231 | G35: =Inputs!$B$17*E35+(1-Inputs!$B$17)*F35 -> 0.007166886
A36: 33 | B36: 45916 | C36: 2485.68 | D36: =C36/C35-1 -> -0.01394382 | E36: =STDEV(OFFSET(D36,-MIN(Inputs!$B$16-1,36-5),0,MIN(Inputs!$B$16,36-4+1),1)) -> 0.0084986904 | F36: =STDEV(D$5:D36) -> 0.0072947558 | G36: =Inputs!$B$17*E36+(1-Inputs!$B$17)*F36 -> 0.00813751
A37: 34 | B37: 45917 | C37: 2423.54 | D37: =C37/C36-1 -> -0.024999195 | E37: =STDEV(OFFSET(D37,-MIN(Inputs!$B$16-1,37-5),0,MIN(Inputs!$B$16,37-4+1),1)) -> 0.008416311 | F37: =STDEV(D$5:D37) -> 0.0084986904 | G37: =Inputs!$B$17*E37+(1-Inputs!$B$17)*F37 -> 0.0084410248
A38: 35 | B38: 45918 | C38: 2411.74 | D38: =C38/C37-1 -> -0.0048689108 | E38: =STDEV(OFFSET(D38,-MIN(Inputs!$B$16-1,38-5),0,MIN(Inputs!$B$16,38-4+1),1)) -> 0.0084049782 | F38: =STDEV(D$5:D38) -> 0.008416311 | G38: =Inputs!$B$17*E38+(1-Inputs!$B$17)*F38 -> 0.0084083781
A39: 36 | B39: 45919 | C39: 2392.54 | D39: =C39/C38-1 -> -0.0079610572 | E39: =STDEV(OFFSET(D39,-MIN(Inputs!$B$16-1,39-5),0,MIN(Inputs!$B$16,39-4+1),1)) -> 0.0084049782 | F39: =STDEV(D$5:D39) -> 0.0084049782 | G39: =Inputs!$B$17*E39+(1-Inputs!$B$17)*F39 -> 0.0084049782
A40: 37 | B40: 45922 | C40: 2416.37 | D40: =C40/C39-1 -> 0.0099601261 | E40: =STDEV(OFFSET(D40,-MIN(Inputs!$B$16-1,40-5),0,MIN(Inputs!$B$16,40-4+1),1)) -> 0.008573502 | F40: =STDEV(D$5:D40) -> 0.0084505125 | G40: =Inputs!$B$17*E40+(1-Inputs!$B$17)*F40 -> 0.0085366052
A41: 38 | B41: 45923 | C41: 2435.32 | D41: =C41/C40-1 -> 0.007842342 | E41: =STDEV(OFFSET(D41,-MIN(Inputs!$B$16-1,41-5),0,MIN(Inputs!$B$16,41-4+1),1)) -> 0.0086677551 | F41: =STDEV(D$5:D41) -> 0.0084259278 | G41: =Inputs!$B$17*E41+(1-Inputs!$B$17)*F41 -> 0.0085952069
...

Sheet Rules
A1: Rules — EWMAC, Carry, Breakout. Raw → scaled → capped
A3: Day | B3: Date | C3: Price | D3: EWMAC64/256: FastEMA | E3: EWMAC64/256: SlowEMA | F3: EWMAC64/256: raw signal | G3: EWMAC64/256: /vol (raw fcst) | H3: EWMAC64/256: scaled | I3: EWMAC64/256: capped | J3: EWMAC16/64: FastEMA | K3: EWMAC16/64: SlowEMA | L3: EWMAC16/64: /vol | M3: EWMAC16/64: capped | N3: Carry raw (annualised) | O3: Carry smoothed | P3: Carry: /vol | Q3: Carry: capped | R3: Breakout40: capped
A4: =Prices!A4 -> 1 | B4: =Prices!B4 -> 45870 | C4: =Prices!C4 -> 2400 | D4: =C4 -> 2400 | E4: =C4 -> 2400 | F4: =D4-E4 -> 0 | J4: =C4 -> 2400 | K4: =C4 -> 2400 | N4: 0.015 | O4: =N4 -> 0.015
A5: =Prices!A5 -> 2 | B5: =Prices!B5 -> 45873 | C5: =Prices!C5 -> 2399.42 | D5: =(2/(Inputs!$B$21+1))*C5+(1-(2/(Inputs!$B$21+1)))*D4 -> 2399.9822 | E5: =(2/(Inputs!$B$22+1))*C5+(1-(2/(Inputs!$B$22+1)))*E4 -> 2399.9955 | F5: =D5-E5 -> -0.013332535 | J5: =(2/(Inputs!$B$23+1))*C5+(1-(2/(Inputs!$B$23+1)))*J4 -> 2399.9318 | K5: =(2/(Inputs!$B$24+1))*C5+(1-(2/(Inputs!$B$24+1)))*K4 -> 2399.9822 | N5: 0.0155 | O5: =(2/(Inputs!$B$26+1))*N5+(1-(2/(Inputs!$B$26+1)))*O4 -> 0.015010989
A6: =Prices!A6 -> 3 | B6: =Prices!B6 -> 45874 | C6: =Prices!C6 -> 2398.15 | D6: =(2/(Inputs!$B$21+1))*C6+(1-(2/(Inputs!$B$21+1)))*D5 -> 2399.9258 | E6: =(2/(Inputs!$B$22+1))*C6+(1-(2/(Inputs!$B$22+1)))*E5 -> 2399.9811 | F6: =D6-E6 -> -0.055344738 | J6: =(2/(Inputs!$B$23+1))*C6+(1-(2/(Inputs!$B$23+1)))*J5 -> 2399.7221 | K6: =(2/(Inputs!$B$24+1))*C6+(1-(2/(Inputs!$B$24+1)))*K5 -> 2399.9258 | N6: 0.015998 | O6: =(2/(Inputs!$B$26+1))*N6+(1-(2/(Inputs!$B$26+1)))*O5 -> 0.015032682
A7: =Prices!A7 -> 4 | B7: =Prices!B7 -> 45875 | C7: =Prices!C7 -> 2398.36 | D7: =(2/(Inputs!$B$21+1))*C7+(1-(2/(Inputs!$B$21+1)))*D6 -> 2399.8776 | E7: =(2/(Inputs!$B$22+1))*C7+(1-(2/(Inputs!$B$22+1)))*E6 -> 2399.9685 | F7: =D7-E7 -> -0.090906825 | J7: =(2/(Inputs!$B$23+1))*C7+(1-(2/(Inputs!$B$23+1)))*J6 -> 2399.5619 | K7: =(2/(Inputs!$B$24+1))*C7+(1-(2/(Inputs!$B$24+1)))*K6 -> 2399.8776 | N7: 0.016494 | O7: =(2/(Inputs!$B$26+1))*N7+(1-(2/(Inputs!$B$26+1)))*O6 -> 0.015064798
A8: =Prices!A8 -> 5 | B8: =Prices!B8 -> 45876 | C8: =Prices!C8 -> 2418.07 | D8: =(2/(Inputs!$B$21+1))*C8+(1-(2/(Inputs!$B$21+1)))*D7 -> 2400.4374 | E8: =(2/(Inputs!$B$22+1))*C8+(1-(2/(Inputs!$B$22+1)))*E7 -> 2400.1094 | F8: =D8-E8 -> 0.32799163 | J8: =(2/(Inputs!$B$23+1))*C8+(1-(2/(Inputs!$B$23+1)))*J7 -> 2401.7393 | K8: =(2/(Inputs!$B$24+1))*C8+(1-(2/(Inputs!$B$24+1)))*K7 -> 2400.4374 | N8: 0.016987 | O8: =(2/(Inputs!$B$26+1))*N8+(1-(2/(Inputs!$B$26+1)))*O7 -> 0.015107045
A9: =Prices!A9 -> 6 | B9: =Prices!B9 -> 45877 | C9: =Prices!C9 -> 2417.89 | D9: =(2/(Inputs!$B$21+1))*C9+(1-(2/(Inputs!$B$21+1)))*D8 -> 2400.9744 | E9: =(2/(Inputs!$B$22+1))*C9+(1-(2/(Inputs!$B$22+1)))*E8 -> 2400.2477 | F9: =D9-E9 -> 0.72662508 | J9: =(2/(Inputs!$B$23+1))*C9+(1-(2/(Inputs!$B$23+1)))*J8 -> 2403.6394 | K9: =(2/(Inputs!$B$24+1))*C9+(1-(2/(Inputs!$B$24+1)))*K8 -> 2400.9744 | N9: 0.017474 | O9: =(2/(Inputs!$B$26+1))*N9+(1-(2/(Inputs!$B$26+1)))*O8 -> 0.015159066
A10: =Prices!A10 -> 7 | B10: =Prices!B10 -> 45880 | C10: =Prices!C10 -> 2384.59 | D10: =(2/(Inputs!$B$21+1))*C10+(1-(2/(Inputs!$B$21+1)))*D9 -> 2400.4702 | E10: =(2/(Inputs!$B$22+1))*C10+(1-(2/(Inputs!$B$22+1)))*E9 -> 2400.1259 | F10: =D10-E10 -> 0.34434072 | J10: =(2/(Inputs!$B$23+1))*C10+(1-(2/(Inputs!$B$23+1)))*J9 -> 2401.3983 | K10: =(2/(Inputs!$B$24+1))*C10+(1-(2/(Inputs!$B$24+1)))*K9 -> 2400.4702 | N10: 0.017955 | O10: =(2/(Inputs!$B$26+1))*N10+(1-(2/(Inputs!$B$26+1)))*O9 -> 0.015220515
A11: =Prices!A11 -> 8 | B11: =Prices!B11 -> 45881 | C11: =Prices!C11 -> 2395.37 | D11: =(2/(Inputs!$B$21+1))*C11+(1-(2/(Inputs!$B$21+1)))*D10 -> 2400.3133 | E11: =(2/(Inputs!$B$22+1))*C11+(1-(2/(Inputs!$B$22+1)))*E10 -> 2400.0889 | F11: =D11-E11 -> 0.2244212 | J11: =(2/(Inputs!$B$23+1))*C11+(1-(2/(Inputs!$B$23+1)))*J10 -> 2400.6891 | K11: =(2/(Inputs!$B$24+1))*C11+(1-(2/(Inputs!$B$24+1)))*K10 -> 2400.3133 | N11: 0.018429 | O11: =(2/(Inputs!$B$26+1))*N11+(1-(2/(Inputs!$B$26+1)))*O10 -> 0.015291031
A12: =Prices!A12 -> 9 | B12: =Prices!B12 -> 45882 | C12: =Prices!C12 -> 2391.85 | D12: =(2/(Inputs!$B$21+1))*C12+(1-(2/(Inputs!$B$21+1)))*D11 -> 2400.0529 | E12: =(2/(Inputs!$B$22+1))*C12+(1-(2/(Inputs!$B$22+1)))*E11 -> 2400.0248 | F12: =D12-E12 -> 0.028127593 | J12: =(2/(Inputs!$B$23+1))*C12+(1-(2/(Inputs!$B$23+1)))*J11 -> 2399.6492 | K12: =(2/(Inputs!$B$24+1))*C12+(1-(2/(Inputs!$B$24+1)))*K11 -> 2400.0529 | N12: 0.018894 | O12: =(2/(Inputs!$B$26+1))*N12+(1-(2/(Inputs!$B$26+1)))*O11 -> 0.015370217
A13: =Prices!A13 -> 10 | B13: =Prices!B13 -> 45883 | C13: =Prices!C13 -> 2389.53 | D13: =(2/(Inputs!$B$21+1))*C13+(1-(2/(Inputs!$B$21+1)))*D12 -> 2399.7291 | E13: =(2/(Inputs!$B$22+1))*C13+(1-(2/(Inputs!$B$22+1)))*E12 -> 2399.9431 | F13: =D13-E13 -> -0.21398251 | J13: =(2/(Inputs!$B$23+1))*C13+(1-(2/(Inputs!$B$23+1)))*J12 -> 2398.4587 | K13: =(2/(Inputs!$B$24+1))*C13+(1-(2/(Inputs!$B$24+1)))*K12 -> 2399.7291 | N13: 0.01935 | O13: =(2/(Inputs!$B$26+1))*N13+(1-(2/(Inputs!$B$26+1)))*O12 -> 0.015457685
A14: =Prices!A14 -> 11 | B14: =Prices!B14 -> 45884 | C14: =Prices!C14 -> 2395.16 | D14: =(2/(Inputs!$B$21+1))*C14+(1-(2/(Inputs!$B$21+1)))*D13 -> 2399.5885 | E14: =(2/(Inputs!$B$22+1))*C14+(1-(2/(Inputs!$B$22+1)))*E13 -> 2399.9059 | F14: =D14-E14 -> -0.31734815 | G14: =F14/(C14*Prices!G14) -> -0.024008965 | H14: =G14*Inputs!$B$29 -> -0.044896764 | I14: =MAX(-Inputs!$B$8,MIN(Inputs!$B$8,H14)) -> -0.044896764 | J14: =(2/(Inputs!$B$23+1))*C14+(1-(2/(Inputs!$B$23+1)))*J13 -> 2398.0706 | K14: =(2/(Inputs!$B$24+1))*C14+(1-(2/(Inputs!$B$24+1)))*K13 -> 2399.5885 | L14: =(J14-K14)/(C14*Prices!G14) -> -0.11483771 | M14: =MAX(-Inputs!$B$8,MIN(Inputs!$B$8,L14*Inputs!$B$30)) -> -0.43064142 | N14: 0.019794 | O14: =(2/(Inputs!$B$26+1))*N14+(1-(2/(Inputs!$B$26+1)))*O13 -> 0.015552988 | P14: =O14/(Prices!G14*SQRT(Inputs!$B$6)) -> 0.17614319 | Q14: =MAX(-Inputs!$B$8,MIN(Inputs!$B$8,P14*Inputs!$B$31)) -> 5.2842957
A15: =Prices!A15 -> 12 | B15: =Prices!B15 -> 45887 | C15: =Prices!C15 -> 2403.6 | D15: =(2/(Inputs!$B$21+1))*C15+(1-(2/(Inputs!$B$21+1)))*D14 -> 2399.712 | E15: =(2/(Inputs!$B$22+1))*C15+(1-(2/(Inputs!$B$22+1)))*E14 -> 2399.9346 | F15: =D15-E15 -> -0.22266629 | G15: =F15/(C15*Prices!G15) -> -0.015189558 | H15: =G15*Inputs!$B$29 -> -0.028404474 | I15: =MAX(-Inputs!$B$8,MIN(Inputs!$B$8,H15)) -> -0.028404474 | J15: =(2/(Inputs!$B$23+1))*C15+(1-(2/(Inputs!$B$23+1)))*J14 -> 2398.7211 | K15: =(2/(Inputs!$B$24+1))*C15+(1-(2/(Inputs!$B$24+1)))*K14 -> 2399.712 | L15: =(J15-K15)/(C15*Prices!G15) -> -0.067590984 | M15: =MAX(-Inputs!$B$8,MIN(Inputs!$B$8,L15*Inputs!$B$30)) -> -0.25346619 | N15: 0.020227 | O15: =(2/(Inputs!$B$26+1))*N15+(1-(2/(Inputs!$B$26+1)))*O14 -> 0.015655714 | P15: =O15/(Prices!G15*SQRT(Inputs!$B$6)) -> 0.16043745 | Q15: =MAX(-Inputs!$B$8,MIN(Inputs!$B$8,P15*Inputs!$B$31)) -> 4.8131236
A16: =Prices!A16 -> 13 | B16: =Prices!B16 -> 45888 | C16: =Prices!C16 -> 2434.45 | D16: =(2/(Inputs!$B$21+1))*C16+(1-(2/(Inputs!$B$21+1)))*D15 -> 2400.7808 | E16: =(2/(Inputs!$B$22+1))*C16+(1-(2/(Inputs!$B$22+1)))*E15 -> 2400.2032 | F16: =D16-E16 -> 0.57759439 | G16: =F16/(C16*Prices!G16) -> 0.037269759 | H16: =G16*Inputs!$B$29 -> 0.069694449 | I16: =MAX(-Inputs!$B$8,MIN(Inputs!$B$8,H16)) -> 0.069694449 | J16: =(2/(Inputs!$B$23+1))*C16+(1-(2/(Inputs!$B$23+1)))*J15 -> 2402.9245 | K16: =(2/(Inputs!$B$24+1))*C16+(1-(2/(Inputs!$B$24+1)))*K15 -> 2400.7808 | L16: =(J16-K16)/(C16*Prices!G16) -> 0.13832441 | M16: =MAX(-Inputs!$B$8,MIN(Inputs!$B$8,L16*Inputs!$B$30)) -> 0.51871655 | N16: 0.020646 | O16: =(2/(Inputs!$B$26+1))*N16+(1-(2/(Inputs!$B$26+1)))*O15 -> 0.015765391 | P16: =O16/(Prices!G16*SQRT(Inputs!$B$6)) -> 0.15478156 | Q16: =MAX(-Inputs!$B$8,MIN(Inputs!$B$8,P16*Inputs!$B$31)) -> 4.6434469
A17: =Prices!A17 -> 14 | B17: =Prices!B17 -> 45889 | C17: =Prices!C17 -> 2453.36 | D17: =(2/(Inputs!$B$21+1))*C17+(1-(2/(Inputs!$B$21+1)))*D16 -> 2402.3986 | E17: =(2/(Inputs!$B$22+1))*C17+(1-(2/(Inputs!$B$22+1)))*E16 -> 2400.6169 | F17: =D17-E17 -> 1.7817439 | G17: =F17/(C17*Prices!G17) -> 0.11730715 | H17: =G17*Inputs!$B$29 -> 0.21936438 | I17: =MAX(-Inputs!$B$8,MIN(Inputs!$B$8,H17)) -> 0.21936438 | J17: =(2/(Inputs!$B$23+1))*C17+(1-(2/(Inputs!$B$23+1)))*J16 -> 2408.8581 | K17: =(2/(Inputs!$B$24+1))*C17+(1-(2/(Inputs!$B$24+1)))*K16 -> 2402.3986 | L17: =(J17-K17)/(C17*Prices!G17) -> 0.42528113 | M17: =MAX(-Inputs!$B$8,MIN(Inputs!$B$8,L17*Inputs!$B$30)) -> 1.5948043 | N17: 0.021052 | O17: =(2/(Inputs!$B$26+1))*N17+(1-(2/(Inputs!$B$26+1)))*O16 -> 0.01588158 | P17: =O17/(Prices!G17*SQRT(Inputs!$B$6)) -> 0.16032979 | Q17: =MAX(-Inputs!$B$8,MIN(Inputs!$B$8,P17*Inputs!$B$31)) -> 4.8098936
A18: =Prices!A18 -> 15 | B18: =Prices!B18 -> 45890 | C18: =Prices!C18 -> 2459.01 | D18: =(2/(Inputs!$B$21+1))*C18+(1-(2/(Inputs!$B$21+1)))*D17 -> 2404.1405 | E18: =(2/(Inputs!$B$22+1))*C18+(1-(2/(Inputs!$B$22+1)))*E17 -> 2401.0713 | F18: =D18-E18 -> 3.0692108 | G18: =F18/(C18*Prices!G18) -> 0.20121357 | H18: =G18*Inputs!$B$29 -> 0.37626937 | I18: =MAX(-Inputs!$B$8,MIN(Inputs!$B$8,H18)) -> 0.37626937 | J18: =(2/(Inputs!$B$23+1))*C18+(1-(2/(Inputs!$B$23+1)))*J17 -> 2414.7583 | K18: =(2/(Inputs!$B$24+1))*C18+(1-(2/(Inputs!$B$24+1)))*K17 -> 2404.1405 | L18: =(J18-K18)/(C18*Prices!G18) -> 0.69608977 | M18: =MAX(-Inputs!$B$8,MIN(Inputs!$B$8,L18*Inputs!$B$30)) -> 2.6103367 | N18: 0.021442 | O18: =(2/(Inputs!$B$26+1))*N18+(1-(2/(Inputs!$B$26+1)))*O17 -> 0.016003787 | P18: =O18/(Prices!G18*SQRT(Inputs!$B$6)) -> 0.16124773 | Q18: =MAX(-Inputs!$B$8,MIN(Inputs!$B$8,P18*Inputs!$B$31)) -> 4.8374319
A19: =Prices!A19 -> 16 | B19: =Prices!B19 -> 45891 | C19: =Prices!C19 -> 2443.81 | D19: =(2/(Inputs!$B$21+1))*C19+(1-(2/(Inputs!$B$21+1)))*D18 -> 2405.3611 | E19: =(2/(Inputs!$B$22+1))*C19+(1-(2/(Inputs!$B$22+1)))*E18 -> 2401.4039 | F19: =D19-E19 -> 3.9572132 | G19: =F19/(C19*Prices!G19) -> 0.25097456 | H19: =G19*Inputs!$B$29 -> 0.46932243 | I19: =MAX(-Inputs!$B$8,MIN(Inputs!$B$8,H19)) -> 0.46932243 | J19: =(2/(Inputs!$B$23+1))*C19+(1-(2/(Inputs!$B$23+1)))*J18 -> 2418.1762 | K19: =(2/(Inputs!$B$24+1))*C19+(1-(2/(Inputs!$B$24+1)))*K18 -> 2405.3611 | L19: =(J19-K19)/(C19*Prices!G19) -> 0.8127566 | M19: =MAX(-Inputs!$B$8,MIN(Inputs!$B$8,L19*Inputs!$B$30)) -> 3.0478373 | N19: 0.021816 | O19: =(2/(Inputs!$B$26+1))*N19+(1-(2/(Inputs!$B$26+1)))*O18 -> 0.016131528 | P19: =O19/(Prices!G19*SQRT(Inputs!$B$6)) -> 0.15626554 | Q19: =MAX(-Inputs!$B$8,MIN(Inputs!$B$8,P19*Inputs!$B$31)) -> 4.6879662
A20: =Prices!A20 -> 17 | B20: =Prices!B20 -> 45894 | C20: =Prices!C20 -> 2421.95 | D20: =(2/(Inputs!$B$21+1))*C20+(1-(2/(Inputs!$B$21+1)))*D19 -> 2405.8716 | E20: =(2/(Inputs!$B$22+1))*C20+(1-(2/(Inputs!$B$22+1)))*E19 -> 2401.5638 | F20: =D20-E20 -> 4.3077483 | G20: =F20/(C20*Prices!G20) -> 0.27670405 | H20: =G20*Inputs!$B$29 -> 0.51743658 | I20: =MAX(-Inputs!$B$8,MIN(Inputs!$B$8,H20)) -> 0.51743658 | J20: =(2/(Inputs!$B$23+1))*C20+(1-(2/(Inputs!$B$23+1)))*J19 -> 2418.6202 | K20: =(2/(Inputs!$B$24+1))*C20+(1-(2/(Inputs!$B$24+1)))*K19 -> 2405.8716 | L20: =(J20-K20)/(C20*Prices!G20) -> 0.81889406 | M20: =MAX(-Inputs!$B$8,MIN(Inputs!$B$8,L20*Inputs!$B$30)) -> 3.0708527 | N20: 0.022174 | O20: =(2/(Inputs!$B$26+1))*N20+(1-(2/(Inputs!$B$26+1)))*O19 -> 0.016264329 | P20: =O20/(Prices!G20*SQRT(Inputs!$B$6)) -> 0.15814176 | Q20: =MAX(-Inputs!$B$8,MIN(Inputs!$B$8,P20*Inputs!$B$31)) -> 4.7442527
A21: =Prices!A21 -> 18 | B21: =Prices!B21 -> 45895 | C21: =Prices!C21 -> 2430.82 | D21: =(2/(Inputs!$B$21+1))*C21+(1-(2/(Inputs!$B$21+1)))*D20 -> 2406.6392 | E21: =(2/(Inputs!$B$22+1))*C21+(1-(2/(Inputs!$B$22+1)))*E20 -> 2401.7915 | F21: =D21-E21 -> 4.8477181 | G21: =F21/(C21*Prices!G21) -> 0.29380872 | H21: =G21*Inputs!$B$29 -> 0.5494223 | I21: =MAX(-Inputs!$B$8,MIN(Inputs!$B$8,H21)) -> 0.5494223 | J21: =(2/(Inputs!$B$23+1))*C21+(1-(2/(Inputs!$B$23+1)))*J20 -> 2420.0554 | K21: =(2/(Inputs!$B$24+1))*C21+(1-(2/(Inputs!$B$24+1)))*K20 -> 2406.6392 | L21: =(J21-K21)/(C21*Prices!G21) -> 0.81312606 | M21: =MAX(-Inputs!$B$8,MIN(Inputs!$B$8,L21*Inputs!$B$30)) -> 3.0492227 | N21: 0.022513 | O21: =(2/(Inputs!$B$26+1))*N21+(1-(2/(Inputs!$B$26+1)))*O20 -> 0.016401663 | P21: =O21/(Prices!G21*SQRT(Inputs!$B$6)) -> 0.15102471 | Q21: =MAX(-Inputs!$B$8,MIN(Inputs!$B$8,P21*Inputs!$B$31)) -> 4.5307414
A22: =Prices!A22 -> 19 | B22: =Prices!B22 -> 45896 | C22: =Prices!C22 -> 2465.61 | D22: =(2/(Inputs!$B$21+1))*C22+(1-(2/(Inputs!$B$21+1)))*D21 -> 2408.4537 | E22: =(2/(Inputs!$B$22+1))*C22+(1-(2/(Inputs!$B$22+1)))*E21 -> 2402.2881 | F22: =D22-E22 -> 6.165562 | G22: =F22/(C22*Prices!G22) -> 0.36635803 | H22: =G22*Inputs!$B$29 -> 0.68508952 | I22: =MAX(-Inputs!$B$8,MIN(Inputs!$B$8,H22)) -> 0.68508952 | J22: =(2/(Inputs!$B$23+1))*C22+(1-(2/(Inputs!$B$23+1)))*J21 -> 2425.4148 | K22: =(2/(Inputs!$B$24+1))*C22+(1-(2/(Inputs!$B$24+1)))*K21 -> 2408.4537 | L22: =(J22-K22)/(C22*Prices!G22) -> 1.0078299 | M22: =MAX(-Inputs!$B$8,MIN(Inputs!$B$8,L22*Inputs!$B$30)) -> 3.7793621 | N22: 0.022833 | O22: =(2/(Inputs!$B$26+1))*N22+(1-(2/(Inputs!$B$26+1)))*O21 -> 0.016543011 | P22: =O22/(Prices!G22*SQRT(Inputs!$B$6)) -> 0.15147885 | Q22: =MAX(-Inputs!$B$8,MIN(Inputs!$B$8,P22*Inputs!$B$31)) -> 4.5443655
A23: =Prices!A23 -> 20 | B23: =Prices!B23 -> 45897 | C23: =Prices!C23 -> 2469.59 | D23: =(2/(Inputs!$B$21+1))*C23+(1-(2/(Inputs!$B$21+1)))*D22 -> 2410.3348 | E23: =(2/(Inputs!$B$22+1))*C23+(1-(2/(Inputs!$B$22+1)))*E22 -> 2402.8119 | F23: =D23-E23 -> 7.5229294 | G23: =F23/(C23*Prices!G23) -> 0.45838413 | H23: =G23*Inputs!$B$29 -> 0.85717832 | I23: =MAX(-Inputs!$B$8,MIN(Inputs!$B$8,H23)) -> 0.85717832 | J23: =(2/(Inputs!$B$23+1))*C23+(1-(2/(Inputs!$B$23+1)))*J22 -> 2430.6119 | K23: =(2/(Inputs!$B$24+1))*C23+(1-(2/(Inputs!$B$24+1)))*K22 -> 2410.3348 | L23: =(J23-K23)/(C23*Prices!G23) -> 1.2355145 | M23: =MAX(-Inputs!$B$8,MIN(Inputs!$B$8,L23*Inputs!$B$30)) -> 4.6331793 | N23: 0.023134 | O23: =(2/(Inputs!$B$26+1))*N23+(1-(2/(Inputs!$B$26+1)))*O22 -> 0.016687868 | P23: =O23/(Prices!G23*SQRT(Inputs!$B$6)) -> 0.1569453 | Q23: =MAX(-Inputs!$B$8,MIN(Inputs!$B$8,P23*Inputs!$B$31)) -> 4.708359
A24: =Prices!A24 -> 21 | B24: =Prices!B24 -> 45898 | C24: =Prices!C24 -> 2469.93 | D24: =(2/(Inputs!$B$21+1))*C24+(1-(2/(Inputs!$B$21+1)))*D23 -> 2412.1685 | E24: =(2/(Inputs!$B$22+1))*C24+(1-(2/(Inputs!$B$22+1)))*E23 -> 2403.3342 | F24: =D24-E24 -> 8.8343077 | G24: =F24/(C24*Prices!G24) -> 0.54667757 | H24: =G24*Inputs!$B$29 -> 1.0222871 | I24: =MAX(-Inputs!$B$8,MIN(Inputs!$B$8,H24)) -> 1.0222871 | J24: =(2/(Inputs!$B$23+1))*C24+(1-(2/(Inputs!$B$23+1)))*J23 -> 2435.2375 | K24: =(2/(Inputs!$B$24+1))*C24+(1-(2/(Inputs!$B$24+1)))*K23 -> 2412.1685 | L24: =(J24-K24)/(C24*Prices!G24) -> 1.4275396 | M24: =MAX(-Inputs!$B$8,MIN(Inputs!$B$8,L24*Inputs!$B$30)) -> 5.3532737 | N24: 0.023415 | O24: =(2/(Inputs!$B$26+1))*N24+(1-(2/(Inputs!$B$26+1)))*O23 -> 0.016835717 | P24: =O24/(Prices!G24*SQRT(Inputs!$B$6)) -> 0.16082554 | Q24: =MAX(-Inputs!$B$8,MIN(Inputs!$B$8,P24*Inputs!$B$31)) -> 4.8247661
A25: =Prices!A25 -> 22 | B25: =Prices!B25 -> 45901 | C25: =Prices!C25 -> 2486.03 | D25: =(2/(Inputs!$B$21+1))*C25+(1-(2/(Inputs!$B$21+1)))*D24 -> 2414.4412 | E25: =(2/(Inputs!$B$22+1))*C25+(1-(2/(Inputs!$B$22+1)))*E24 -> 2403.9777 | F25: =D25-E25 -> 10.463422 | G25: =F25/(C25*Prices!G25) -> 0.60612319 | H25: =G25*Inputs!$B$29 -> 1.1334504 | I25: =MAX(-Inputs!$B$8,MIN(Inputs!$B$8,H25)) -> 1.1334504 | J25: =(2/(Inputs!$B$23+1))*C25+(1-(2/(Inputs!$B$23+1)))*J24 -> 2441.2131 | K25: =(2/(Inputs!$B$24+1))*C25+(1-(2/(Inputs!$B$24+1)))*K24 -> 2414.4412 | L25: =(J25-K25)/(C25*Prices!G25) -> 1.5508411 | M25: =MAX(-Inputs!$B$8,MIN(Inputs!$B$8,L25*Inputs!$B$30)) -> 5.815654 | N25: 0.023674 | O25: =(2/(Inputs!$B$26+1))*N25+(1-(2/(Inputs!$B$26+1)))*O24 -> 0.016986009 | P25: =O25/(Prices!G25*SQRT(Inputs!$B$6)) -> 0.152885 | Q25: =MAX(-Inputs!$B$8,MIN(Inputs!$B$8,P25*Inputs!$B$31)) -> 4.5865501
... A48: =Prices!A48 -> 45 | B48: =Prices!B48 -> 45932 | C48: =Prices!C48 -> 2435.31 | D48: =(2/(Inputs!$B$21+1))*C48+(1-(2/(Inputs!$B$21+1)))*D47 -> 2430.3826 | E48: =(2/(Inputs!$B$22+1))*C48+(1-(2/(Inputs!$B$22+1)))*E47 -> 2411.4972 | F48: =D48-E48 -> 18.885471 | G48: =F48/(C48*Prices!G48) -> 0.89412847 | H48: =G48*Inputs!$B$29 -> 1.6720202 | I48: =MAX(-Inputs!$B$8,MIN(Inputs!$B$8,H48)) -> 1.6720202 | J48: =(2/(Inputs!$B$23+1))*C48+(1-(2/(Inputs!$B$23+1)))*J47 -> 2431.7283 | K48: =(2/(Inputs!$B$24+1))*C48+(1-(2/(Inputs!$B$24+1)))*K47 -> 2430.3826 | L48: =(J48-K48)/(C48*Prices!G48) -> 0.063710513 | M48: =MAX(-Inputs!$B$8,MIN(Inputs!$B$8,L48*Inputs!$B$30)) -> 0.23891442 | N48: 0.023085 | O48: =(2/(Inputs!$B$26+1))*N48+(1-(2/(Inputs!$B$26+1)))*O47 -> 0.019947981 | P48: =O48/(Prices!G48*SQRT(Inputs!$B$6)) -> 0.14374916 | Q48: =MAX(-Inputs!$B$8,MIN(Inputs!$B$8,P48*Inputs!$B$31)) -> 4.3124747
A49: =Prices!A49 -> 46 | B49: =Prices!B49 -> 45933 | C49: =Prices!C49 -> 2453.78 | D49: =(2/(Inputs!$B$21+1))*C49+(1-(2/(Inputs!$B$21+1)))*D48 -> 2431.1025 | E49: =(2/(Inputs!$B$22+1))*C49+(1-(2/(Inputs!$B$22+1)))*E48 -> 2411.8262 | F49: =D49-E49 -> 19.276341 | G49: =F49/(C49*Prices!G49) -> 0.90108297 | H49: =G49*Inputs!$B$29 -> 1.6850252 | I49: =MAX(-Inputs!$B$8,MIN(Inputs!$B$8,H49)) -> 1.6850252 | J49: =(2/(Inputs!$B$23+1))*C49+(1-(2/(Inputs!$B$23+1)))*J48 -> 2434.3226 | K49: =(2/(Inputs!$B$24+1))*C49+(1-(2/(Inputs!$B$24+1)))*K48 -> 2431.1025 | L49: =(J49-K49)/(C49*Prices!G49) -> 0.15052393 | M49: =MAX(-Inputs!$B$8,MIN(Inputs!$B$8,L49*Inputs!$B$30)) -> 0.56446474 | N49: 0.022781 | O49: =(2/(Inputs!$B$26+1))*N49+(1-(2/(Inputs!$B$26+1)))*O48 -> 0.020010245 | P49: =O49/(Prices!G49*SQRT(Inputs!$B$6)) -> 0.14345253 | Q49: =MAX(-Inputs!$B$8,MIN(Inputs!$B$8,P49*Inputs!$B$31)) -> 4.303576 | R49: =MAX(-Inputs!$B$8,MIN(Inputs!$B$8,Inputs!$B$32*(40*(C49-AVERAGE(OFFSET(Prices!C49,-(Inputs!$B$25-1),0,Inputs!$B$25,1)))/(MAX(OFFSET(Prices!C49,-(Inputs!$B$25-1),0,Inputs!$B$25,1))-MIN(OFFSET(Prices!C49,-(Inputs!$B$25-1),0,Inputs!$B$25,1)))))) -> 2.0793089
A50: =Prices!A50 -> 47 | B50: =Prices!B50 -> 45936 | C50: =Prices!C50 -> 2465.31 | D50: =(2/(Inputs!$B$21+1))*C50+(1-(2/(Inputs!$B$21+1)))*D49 -> 2432.1551 | E50: =(2/(Inputs!$B$22+1))*C50+(1-(2/(Inputs!$B$22+1)))*E49 -> 2412.2424 | F50: =D50-E50 -> 19.912662 | G50: =F50/(C50*Prices!G50) -> 0.92770845 | H50: =G50*Inputs!$B$29 -> 1.7348148 | I50: =MAX(-Inputs!$B$8,MIN(Inputs!$B$8,H50)) -> 1.7348148 | J50: =(2/(Inputs!$B$23+1))*C50+(1-(2/(Inputs!$B$23+1)))*J49 -> 2437.9682 | K50: =(2/(Inputs!$B$24+1))*C50+(1-(2/(Inputs!$B$24+1)))*K49 -> 2432.1551 | L50: =(J50-K50)/(C50*Prices!G50) -> 0.27082615 | M50: =MAX(-Inputs!$B$8,MIN(Inputs!$B$8,L50*Inputs!$B$30)) -> 1.0155981 | N50: 0.022457 | O50: =(2/(Inputs!$B$26+1))*N50+(1-(2/(Inputs!$B$26+1)))*O49 -> 0.02006402 | P50: =O50/(Prices!G50*SQRT(Inputs!$B$6)) -> 0.14402958 | Q50: =MAX(-Inputs!$B$8,MIN(Inputs!$B$8,P50*Inputs!$B$31)) -> 4.3208874 | R50: =MAX(-Inputs!$B$8,MIN(Inputs!$B$8,Inputs!$B$32*(40*(C50-AVERAGE(OFFSET(Prices!C50,-(Inputs!$B$25-1),0,Inputs!$B$25,1)))/(MAX(OFFSET(Prices!C50,-(Inputs!$B$25-1),0,Inputs!$B$25,1))-MIN(OFFSET(Prices!C50,-(Inputs!$B$25-1),0,Inputs!$B$25,1)))))) -> 4.0667194
A51: =Prices!A51 -> 48 | B51: =Prices!B51 -> 45937 | C51: =Prices!C51 -> 2484.29 | D51: =(2/(Inputs!$B$21+1))*C51+(1-(2/(Inputs!$B$21+1)))*D50 -> 2433.7592 | E51: =(2/(Inputs!$B$22+1))*C51+(1-(2/(Inputs!$B$22+1)))*E50 -> 2412.8031 | F51: =D51-E51 -> 20.956132 | G51: =F51/(C51*Prices!G51) -> 0.98258403 | H51: =G51*Inputs!$B$29 -> 1.8374321 | I51: =MAX(-Inputs!$B$8,MIN(Inputs!$B$8,H51)) -> 1.8374321 | J51: =(2/(Inputs!$B$23+1))*C51+(1-(2/(Inputs!$B$23+1)))*J50 -> 2443.4178 | K51: =(2/(Inputs!$B$24+1))*C51+(1-(2/(Inputs!$B$24+1)))*K50 -> 2433.7592 | L51: =(J51-K51)/(C51*Prices!G51) -> 0.45286833 | M51: =MAX(-Inputs!$B$8,MIN(Inputs!$B$8,L51*Inputs!$B$30)) -> 1.6982562 | N51: 0.022115 | O51: =(2/(Inputs!$B$26+1))*N51+(1-(2/(Inputs!$B$26+1)))*O50 -> 0.020109096 | P51: =O51/(Prices!G51*SQRT(Inputs!$B$6)) -> 0.14639743 | Q51: =MAX(-Inputs!$B$8,MIN(Inputs!$B$8,P51*Inputs!$B$31)) -> 4.3919228 | R51: =MAX(-Inputs!$B$8,MIN(Inputs!$B$8,Inputs!$B$32*(40*(C51-AVERAGE(OFFSET(Prices!C51,-(Inputs!$B$25-1),0,Inputs!$B$25,1)))/(MAX(OFFSET(Prices!C51,-(Inputs!$B$25-1),0,Inputs!$B$25,1))-MIN(OFFSET(Prices!C51,-(Inputs!$B$25-1),0,Inputs!$B$25,1)))))) -> 7.4378646
A52: =Prices!A52 -> 49 | B52: =Prices!B52 -> 45938 | C52: =Prices!C52 -> 2499.16 | D52: =(2/(Inputs!$B$21+1))*C52+(1-(2/(Inputs!$B$21+1)))*D51 -> 2435.7716 | E52: =(2/(Inputs!$B$22+1))*C52+(1-(2/(Inputs!$B$22+1)))*E51 -> 2413.4751 | F52: =D52-E52 -> 22.296425 | G52: =F52/(C52*Prices!G52) -> 1.044319 | H52: =G52*Inputs!$B$29 -> 1.9528764 | I52: =MAX(-Inputs!$B$8,MIN(Inputs!$B$8,H52)) -> 1.9528764 | J52: =(2/(Inputs!$B$23+1))*C52+(1-(2/(Inputs!$B$23+1)))*J51 -> 2449.9757 | K52: =(2/(Inputs!$B$24+1))*C52+(1-(2/(Inputs!$B$24+1)))*K51 -> 2435.7716 | L52: =(J52-K52)/(C52*Prices!G52) -> 0.66529357 | M52: =MAX(-Inputs!$B$8,MIN(Inputs!$B$8,L52*Inputs!$B$30)) -> 2.4948509 | N52: 0.021755 | O52: =(2/(Inputs!$B$26+1))*N52+(1-(2/(Inputs!$B$26+1)))*O51 -> 0.02014527 | P52: =O52/(Prices!G52*SQRT(Inputs!$B$6)) -> 0.14738222 | Q52: =MAX(-Inputs!$B$8,MIN(Inputs!$B$8,P52*Inputs!$B$31)) -> 4.4214666 | R52: =MAX(-Inputs!$B$8,MIN(Inputs!$B$8,Inputs!$B$32*(40*(C52-AVERAGE(OFFSET(Prices!C52,-(Inputs!$B$25-1),0,Inputs!$B$25,1)))/(MAX(OFFSET(Prices!C52,-(Inputs!$B$25-1),0,Inputs!$B$25,1))-MIN(OFFSET(Prices!C52,-(Inputs!$B$25-1),0,Inputs!$B$25,1)))))) -> 9.8896752
A53: =Prices!A53 -> 50 | B53: =Prices!B53 -> 45939 | C53: =Prices!C53 -> 2486.49 | D53: =(2/(Inputs!$B$21+1))*C53+(1-(2/(Inputs!$B$21+1)))*D52 -> 2437.3321 | E53: =(2/(Inputs!$B$22+1))*C53+(1-(2/(Inputs!$B$22+1)))*E52 -> 2414.0433 | F53: =D53-E53 -> 23.288783 | G53: =F53/(C53*Prices!G53) -> 1.0938017 | H53: =G53*Inputs!$B$29 -> 2.0454091 | I53: =MAX(-Inputs!$B$8,MIN(Inputs!$B$8,H53)) -> 2.0454091 | J53: =(2/(Inputs!$B$23+1))*C53+(1-(2/(Inputs!$B$23+1)))*J52 -> 2454.2715 | K53: =(2/(Inputs!$B$24+1))*C53+(1-(2/(Inputs!$B$24+1)))*K52 -> 2437.3321 | L53: =(J53-K53)/(C53*Prices!G53) -> 0.79559022 | M53: =MAX(-Inputs!$B$8,MIN(Inputs!$B$8,L53*Inputs!$B$30)) -> 2.9834633 | N53: 0.021378 | O53: =(2/(Inputs!$B$26+1))*N53+(1-(2/(Inputs!$B$26+1)))*O52 -> 0.020172363 | P53: =O53/(Prices!G53*SQRT(Inputs!$B$6)) -> 0.14723643 | Q53: =MAX(-Inputs!$B$8,MIN(Inputs!$B$8,P53*Inputs!$B$31)) -> 4.417093 | R53: =MAX(-Inputs!$B$8,MIN(Inputs!$B$8,Inputs!$B$32*(40*(C53-AVERAGE(OFFSET(Prices!C53,-(Inputs!$B$25-1),0,Inputs!$B$25,1)))/(MAX(OFFSET(Prices!C53,-(Inputs!$B$25-1),0,Inputs!$B$25,1))-MIN(OFFSET(Prices!C53,-(Inputs!$B$25-1),0,Inputs!$B$25,1)))))) -> 7.0045752
A54: =Prices!A54 -> 51 | B54: =Prices!B54 -> 45940 | C54: =Prices!C54 -> 2471.64 | D54: =(2/(Inputs!$B$21+1))*C54+(1-(2/(Inputs!$B$21+1)))*D53 -> 2438.3878 | E54: =(2/(Inputs!$B$22+1))*C54+(1-(2/(Inputs!$B$22+1)))*E53 -> 2414.4916 | F54: =D54-E54 -> 23.896187 | G54: =F54/(C54*Prices!G54) -> 1.1305301 | H54: =G54*Inputs!$B$29 -> 2.1140913 | I54: =MAX(-Inputs!$B$8,MIN(Inputs!$B$8,H54)) -> 2.1140913 | J54: =(2/(Inputs!$B$23+1))*C54+(1-(2/(Inputs!$B$23+1)))*J53 -> 2456.3149 | K54: =(2/(Inputs!$B$24+1))*C54+(1-(2/(Inputs!$B$24+1)))*K53 -> 2438.3878 | L54: =(J54-K54)/(C54*Prices!G54) -> 0.84813268 | M54: =MAX(-Inputs!$B$8,MIN(Inputs!$B$8,L54*Inputs!$B$30)) -> 3.1804976 | N54: 0.020985 | O54: =(2/(Inputs!$B$26+1))*N54+(1-(2/(Inputs!$B$26+1)))*O53 -> 0.020190223 | P54: =O54/(Prices!G54*SQRT(Inputs!$B$6)) -> 0.14755702 | Q54: =MAX(-Inputs!$B$8,MIN(Inputs!$B$8,P54*Inputs!$B$31)) -> 4.4267105 | R54: =MAX(-Inputs!$B$8,MIN(Inputs!$B$8,Inputs!$B$32*(40*(C54-AVERAGE(OFFSET(Prices!C54,-(Inputs!$B$25-1),0,Inputs!$B$25,1)))/(MAX(OFFSET(Prices!C54,-(Inputs!$B$25-1),0,Inputs!$B$25,1))-MIN(OFFSET(Prices!C54,-(Inputs!$B$25-1),0,Inputs!$B$25,1)))))) -> 3.5578835
A55: =Prices!A55 -> 52 | B55: =Prices!B55 -> 45943 | C55: =Prices!C55 -> 2462.99 | D55: =(2/(Inputs!$B$21+1))*C55+(1-(2/(Inputs!$B$21+1)))*D54 -> 2439.1447 | E55: =(2/(Inputs!$B$22+1))*C55+(1-(2/(Inputs!$B$22+1)))*E54 -> 2414.869 | F55: =D55-E55 -> 24.275759 | G55: =F55/(C55*Prices!G55) -> 1.166672 | H55: =G55*Inputs!$B$29 -> 2.1816767 | I55: =MAX(-Inputs!$B$8,MIN(Inputs!$B$8,H55)) -> 2.1816767 | J55: =(2/(Inputs!$B$23+1))*C55+(1-(2/(Inputs!$B$23+1)))*J54 -> 2457.1002 | K55: =(2/(Inputs!$B$24+1))*C55+(1-(2/(Inputs!$B$24+1)))*K54 -> 2439.1447 | L55: =(J55-K55)/(C55*Prices!G55) -> 0.86292235 | M55: =MAX(-Inputs!$B$8,MIN(Inputs!$B$8,L55*Inputs!$B$30)) -> 3.2359588 | N55: 0.020577 | O55: =(2/(Inputs!$B$26+1))*N55+(1-(2/(Inputs!$B$26+1)))*O54 -> 0.020198724 | P55: =O55/(Prices!G55*SQRT(Inputs!$B$6)) -> 0.14943164 | Q55: =MAX(-Inputs!$B$8,MIN(Inputs!$B$8,P55*Inputs!$B$31)) -> 4.4829491 | R55: =MAX(-Inputs!$B$8,MIN(Inputs!$B$8,Inputs!$B$32*(40*(C55-AVERAGE(OFFSET(Prices!C55,-(Inputs!$B$25-1),0,Inputs!$B$25,1)))/(MAX(OFFSET(Prices!C55,-(Inputs!$B$25-1),0,Inputs!$B$25,1))-MIN(OFFSET(Prices!C55,-(Inputs!$B$25-1),0,Inputs!$B$25,1)))))) -> 1.4739223
A56: =Prices!A56 -> 53 | B56: =Prices!B56 -> 45944 | C56: =Prices!C56 -> 2478.24 | D56: =(2/(Inputs!$B$21+1))*C56+(1-(2/(Inputs!$B$21+1)))*D55 -> 2440.3477 | E56: =(2/(Inputs!$B$22+1))*C56+(1-(2/(Inputs!$B$22+1)))*E55 -> 2415.3621 | F56: =D56-E56 -> 24.985531 | G56: =F56/(C56*Prices!G56) -> 1.191374 | H56: =G56*Inputs!$B$29 -> 2.2278693 | I56: =MAX(-Inputs!$B$8,MIN(Inputs!$B$8,H56)) -> 2.2278693 | J56: =(2/(Inputs!$B$23+1))*C56+(1-(2/(Inputs!$B$23+1)))*J55 -> 2459.5872 | K56: =(2/(Inputs!$B$24+1))*C56+(1-(2/(Inputs!$B$24+1)))*K55 -> 2440.3477 | L56: =(J56-K56)/(C56*Prices!G56) -> 0.91739022 | M56: =MAX(-Inputs!$B$8,MIN(Inputs!$B$8,L56*Inputs!$B$30)) -> 3.4402133 | N56: 0.020155 | O56: =(2/(Inputs!$B$26+1))*N56+(1-(2/(Inputs!$B$26+1)))*O55 -> 0.020197763 | P56: =O56/(Prices!G56*SQRT(Inputs!$B$6)) -> 0.14917161 | Q56: =MAX(-Inputs!$B$8,MIN(Inputs!$B$8,P56*Inputs!$B$31)) -> 4.4751483 | R56: =MAX(-Inputs!$B$8,MIN(Inputs!$B$8,Inputs!$B$32*(40*(C56-AVERAGE(OFFSET(Prices!C56,-(Inputs!$B$25-1),0,Inputs!$B$25,1)))/(MAX(OFFSET(Prices!C56,-(Inputs!$B$25-1),0,Inputs!$B$25,1))-MIN(OFFSET(Prices!C56,-(Inputs!$B$25-1),0,Inputs!$B$25,1)))))) -> 4.3846001
A57: =Prices!A57 -> 54 | B57: =Prices!B57 -> 45945 | C57: =Prices!C57 -> 2475.02 | D57: =(2/(Inputs!$B$21+1))*C57+(1-(2/(Inputs!$B$21+1)))*D56 -> 2441.4145 | E57: =(2/(Inputs!$B$22+1))*C57+(1-(2/(Inputs!$B$22+1)))*E56 -> 2415.8264 | F57: =D57-E57 -> 25.588108 | G57: =F57/(C57*Prices!G57) -> 1.2593884 | H57: =G57*Inputs!$B$29 -> 2.3550563 | I57: =MAX(-Inputs!$B$8,MIN(Inputs!$B$8,H57)) -> 2.3550563 | J57: =(2/(Inputs!$B$23+1))*C57+(1-(2/(Inputs!$B$23+1)))*J56 -> 2461.4028 | K57: =(2/(Inputs!$B$24+1))*C57+(1-(2/(Inputs!$B$24+1)))*K56 -> 2441.4145 | L57: =(J57-K57)/(C57*Prices!G57) -> 0.98377942 | M57: =MAX(-Inputs!$B$8,MIN(Inputs!$B$8,L57*Inputs!$B$30)) -> 3.6891728 | N57: 0.01972 | O57: =(2/(Inputs!$B$26+1))*N57+(1-(2/(Inputs!$B$26+1)))*O56 -> 0.020187262 | P57: =O57/(Prices!G57*SQRT(Inputs!$B$6)) -> 0.15369427 | Q57: =MAX(-Inputs!$B$8,MIN(Inputs!$B$8,P57*Inputs!$B$31)) -> 4.6108281 | R57: =MAX(-Inputs!$B$8,MIN(Inputs!$B$8,Inputs!$B$32*(40*(C57-AVERAGE(OFFSET(Prices!C57,-(Inputs!$B$25-1),0,Inputs!$B$25,1)))/(MAX(OFFSET(Prices!C57,-(Inputs!$B$25-1),0,Inputs!$B$25,1))-MIN(OFFSET(Prices!C57,-(Inputs!$B$25-1),0,Inputs!$B$25,1)))))) -> 3.6111405
A58: =Prices!A58 -> 55 | B58: =Prices!B58 -> 45946 | C58: =Prices!C58 -> 2535.8 | D58: =(2/(Inputs!$B$21+1))*C58+(1-(2/(Inputs!$B$21+1)))*D57 -> 2444.3187 | E58: =(2/(Inputs!$B$22+1))*C58+(1-(2/(Inputs!$B$22+1)))*E57 -> 2416.7601 | F58: =D58-E58 -> 27.55863 | G58: =F58/(C58*Prices!G58) -> 1.199901 | H58: =G58*Inputs!$B$29 -> 2.2438149 | I58: =MAX(-Inputs!$B$8,MIN(Inputs!$B$8,H58)) -> 2.2438149 | J58: =(2/(Inputs!$B$23+1))*C58+(1-(2/(Inputs!$B$23+1)))*J57 -> 2470.1554 | K58: =(2/(Inputs!$B$24+1))*C58+(1-(2/(Inputs!$B$24+1)))*K57 -> 2444.3187 | L58: =(J58-K58)/(C58*Prices!G58) -> 1.1249307 | M58: =MAX(-Inputs!$B$8,MIN(Inputs!$B$8,L58*Inputs!$B$30)) -> 4.2184901 | N58: 0.019274 | O58: =(2/(Inputs!$B$26+1))*N58+(1-(2/(Inputs!$B$26+1)))*O57 -> 0.020167191 | P58: =O58/(Prices!G58*SQRT(Inputs!$B$6)) -> 0.13916442 | Q58: =MAX(-Inputs!$B$8,MIN(Inputs!$B$8,P58*Inputs!$B$31)) -> 4.1749326 | R58: =MAX(-Inputs!$B$8,MIN(Inputs!$B$8,Inputs!$B$32*(40*(C58-AVERAGE(OFFSET(Prices!C58,-(Inputs!$B$25-1),0,Inputs!$B$25,1)))/(MAX(OFFSET(Prices!C58,-(Inputs!$B$25-1),0,Inputs!$B$25,1))-MIN(OFFSET(Prices!C58,-(Inputs!$B$25-1),0,Inputs!$B$25,1)))))) -> 14.936591
A59: =Prices!A59 -> 56 | B59: =Prices!B59 -> 45947 | C59: =Prices!C59 -> 2518.07 | D59: =(2/(Inputs!$B$21+1))*C59+(1-(2/(Inputs!$B$21+1)))*D58 -> 2446.588 | E59: =(2/(Inputs!$B$22+1))*C59+(1-(2/(Inputs!$B$22+1)))*E58 -> 2417.5485 | F59: =D59-E59 -> 29.039497 | G59: =F59/(C59*Prices!G59) -> 1.2646138 | H59: =G59*Inputs!$B$29 -> 2.3648279 | I59: =MAX(-Inputs!$B$8,MIN(Inputs!$B$8,H59)) -> 2.3648279 | J59: =(2/(Inputs!$B$23+1))*C59+(1-(2/(Inputs!$B$23+1)))*J58 -> 2475.7925 | K59: =(2/(Inputs!$B$24+1))*C59+(1-(2/(Inputs!$B$24+1)))*K58 -> 2446.588 | L59: =(J59-K59)/(C59*Prices!G59) -> 1.271799 | M59: =MAX(-Inputs!$B$8,MIN(Inputs!$B$8,L59*Inputs!$B$30)) -> 4.7692463 | N59: 0.018817 | O59: =(2/(Inputs!$B$26+1))*N59+(1-(2/(Inputs!$B$26+1)))*O58 -> 0.020137516 | P59: =O59/(Prices!G59*SQRT(Inputs!$B$6)) -> 0.13801382 | Q59: =MAX(-Inputs!$B$8,MIN(Inputs!$B$8,P59*Inputs!$B$31)) -> 4.1404145 | R59: =MAX(-Inputs!$B$8,MIN(Inputs!$B$8,Inputs!$B$32*(40*(C59-AVERAGE(OFFSET(Prices!C59,-(Inputs!$B$25-1),0,Inputs!$B$25,1)))/(MAX(OFFSET(Prices!C59,-(Inputs!$B$25-1),0,Inputs!$B$25,1))-MIN(OFFSET(Prices!C59,-(Inputs!$B$25-1),0,Inputs!$B$25,1)))))) -> 11.108432
A60: =Prices!A60 -> 57 | B60: =Prices!B60 -> 45950 | C60: =Prices!C60 -> 2493.42 | D60: =(2/(Inputs!$B$21+1))*C60+(1-(2/(Inputs!$B$21+1)))*D59 -> 2448.0289 | E60: =(2/(Inputs!$B$22+1))*C60+(1-(2/(Inputs!$B$22+1)))*E59 -> 2418.1389 | F60: =D60-E60 -> 29.890043 | G60: =F60/(C60*Prices!G60) -> 1.3025038 | H60: =G60*Inputs!$B$29 -> 2.435682 | I60: =MAX(-Inputs!$B$8,MIN(Inputs!$B$8,H60)) -> 2.435682 | J60: =(2/(Inputs!$B$23+1))*C60+(1-(2/(Inputs!$B$23+1)))*J59 -> 2477.8663 | K60: =(2/(Inputs!$B$24+1))*C60+(1-(2/(Inputs!$B$24+1)))*K59 -> 2448.0289 | L60: =(J60-K60)/(C60*Prices!G60) -> 1.3002069 | M60: =MAX(-Inputs!$B$8,MIN(Inputs!$B$8,L60*Inputs!$B$30)) -> 4.8757759 | N60: 0.01835 | O60: =(2/(Inputs!$B$26+1))*N60+(1-(2/(Inputs!$B$26+1)))*O59 -> 0.02009823 | P60: =O60/(Prices!G60*SQRT(Inputs!$B$6)) -> 0.13648525 | Q60: =MAX(-Inputs!$B$8,MIN(Inputs!$B$8,P60*Inputs!$B$31)) -> 4.0945575 | R60: =MAX(-Inputs!$B$8,MIN(Inputs!$B$8,Inputs!$B$32*(40*(C60-AVERAGE(OFFSET(Prices!C60,-(Inputs!$B$25-1),0,Inputs!$B$25,1)))/(MAX(OFFSET(Prices!C60,-(Inputs!$B$25-1),0,Inputs!$B$25,1))-MIN(OFFSET(Prices!C60,-(Inputs!$B$25-1),0,Inputs!$B$25,1)))))) -> 5.9414003
... A183: =Prices!A183 -> 180 | B183: =Prices!B183 -> 46121 | C183: =Prices!C183 -> 3127.97 | D183: =(2/(Inputs!$B$21+1))*C183+(1-(2/(Inputs!$B$21+1)))*D182 -> 2906.2682 | E183: =(2/(Inputs!$B$22+1))*C183+(1-(2/(Inputs!$B$22+1)))*E182 -> 2643.6724 | F183: =D183-E183 -> 262.59574 | G183: =F183/(C183*Prices!G183) -> 9.550421 | H183: =G183*Inputs!$B$29 -> 17.859287 | I183: =MAX(-Inputs!$B$8,MIN(Inputs!$B$8,H183)) -> 17.859287 | J183: =(2/(Inputs!$B$23+1))*C183+(1-(2/(Inputs!$B$23+1)))*J182 -> 3094.4686 | K183: =(2/(Inputs!$B$24+1))*C183+(1-(2/(Inputs!$B$24+1)))*K182 -> 2906.2682 | L183: =(J183-K183)/(C183*Prices!G183) -> 6.8447144 | M183: =MAX(-Inputs!$B$8,MIN(Inputs!$B$8,L183*Inputs!$B$30)) -> 20 | N183: 0.019571 | O183: =(2/(Inputs!$B$26+1))*N183+(1-(2/(Inputs!$B$26+1)))*O182 -> 0.019128587 | P183: =O183/(Prices!G183*SQRT(Inputs!$B$6)) -> 0.13600671 | Q183: =MAX(-Inputs!$B$8,MIN(Inputs!$B$8,P183*Inputs!$B$31)) -> 4.0802013 | R183: =MAX(-Inputs!$B$8,MIN(Inputs!$B$8,Inputs!$B$32*(40*(C183-AVERAGE(OFFSET(Prices!C183,-(Inputs!$B$25-1),0,Inputs!$B$25,1)))/(MAX(OFFSET(Prices!C183,-(Inputs!$B$25-1),0,Inputs!$B$25,1))-MIN(OFFSET(Prices!C183,-(Inputs!$B$25-1),0,Inputs!$B$25,1)))))) -> 12.079885

Sheet Combine
A1: Combine — weight, apply FDM, cap
A3: Day | B3: Date | C3: EWMAC64/256 | D3: EWMAC16/64 | E3: Carry | F3: Breakout40 | G3: Weighted sum | H3: × FDM | I3: Final (capped)
A4: =Rules!A4 -> 1 | B4: =Rules!B4 -> 45870 | C4: =Rules!I4 -> 0 | D4: =Rules!M4 -> 0 | E4: =Rules!Q4 -> 0 | F4: =Rules!R4 -> 0
A5: =Rules!A5 -> 2 | B5: =Rules!B5 -> 45873 | C5: =Rules!I5 -> 0 | D5: =Rules!M5 -> 0 | E5: =Rules!Q5 -> 0 | F5: =Rules!R5 -> 0
A6: =Rules!A6 -> 3 | B6: =Rules!B6 -> 45874 | C6: =Rules!I6 -> 0 | D6: =Rules!M6 -> 0 | E6: =Rules!Q6 -> 0 | F6: =Rules!R6 -> 0
A7: =Rules!A7 -> 4 | B7: =Rules!B7 -> 45875 | C7: =Rules!I7 -> 0 | D7: =Rules!M7 -> 0 | E7: =Rules!Q7 -> 0 | F7: =Rules!R7 -> 0
A8: =Rules!A8 -> 5 | B8: =Rules!B8 -> 45876 | C8: =Rules!I8 -> 0 | D8: =Rules!M8 -> 0 | E8: =Rules!Q8 -> 0 | F8: =Rules!R8 -> 0
A9: =Rules!A9 -> 6 | B9: =Rules!B9 -> 45877 | C9: =Rules!I9 -> 0 | D9: =Rules!M9 -> 0 | E9: =Rules!Q9 -> 0 | F9: =Rules!R9 -> 0
A10: =Rules!A10 -> 7 | B10: =Rules!B10 -> 45880 | C10: =Rules!I10 -> 0 | D10: =Rules!M10 -> 0 | E10: =Rules!Q10 -> 0 | F10: =Rules!R10 -> 0
A11: =Rules!A11 -> 8 | B11: =Rules!B11 -> 45881 | C11: =Rules!I11 -> 0 | D11: =Rules!M11 -> 0 | E11: =Rules!Q11 -> 0 | F11: =Rules!R11 -> 0
A12: =Rules!A12 -> 9 | B12: =Rules!B12 -> 45882 | C12: =Rules!I12 -> 0 | D12: =Rules!M12 -> 0 | E12: =Rules!Q12 -> 0 | F12: =Rules!R12 -> 0
A13: =Rules!A13 -> 10 | B13: =Rules!B13 -> 45883 | C13: =Rules!I13 -> 0 | D13: =Rules!M13 -> 0 | E13: =Rules!Q13 -> 0 | F13: =Rules!R13 -> 0
A14: =Rules!A14 -> 11 | B14: =Rules!B14 -> 45884 | C14: =Rules!I14 -> -0.044896764 | D14: =Rules!M14 -> -0.43064142 | E14: =Rules!Q14 -> 5.2842957 | F14: =Rules!R14 -> 0
A15: =Rules!A15 -> 12 | B15: =Rules!B15 -> 45887 | C15: =Rules!I15 -> -0.028404474 | D15: =Rules!M15 -> -0.25346619 | E15: =Rules!Q15 -> 4.8131236 | F15: =Rules!R15 -> 0
... A48: =Rules!A48 -> 45 | B48: =Rules!B48 -> 45932 | C48: =Rules!I48 -> 1.6720202 | D48: =Rules!M48 -> 0.23891442 | E48: =Rules!Q48 -> 4.3124747 | F48: =Rules!R48 -> 0
A49: =Rules!A49 -> 46 | B49: =Rules!B49 -> 45933 | C49: =Rules!I49 -> 1.6850252 | D49: =Rules!M49 -> 0.56446474 | E49: =Rules!Q49 -> 4.303576 | F49: =Rules!R49 -> 2.0793089 | G49: =C49*Inputs!$B$35+D49*Inputs!$B$36+E49*Inputs!$B$37+F49*Inputs!$B$38 -> 2.3805204 | H49: =G49*Inputs!$B$40 -> 3.1184818 | I49: =MAX(-Inputs!$B$8,MIN(Inputs!$B$8,H49)) -> 3.1184818
A50: =Rules!A50 -> 47 | B50: =Rules!B50 -> 45936 | C50: =Rules!I50 -> 1.7348148 | D50: =Rules!M50 -> 1.0155981 | E50: =Rules!Q50 -> 4.3208874 | F50: =Rules!R50 -> 4.0667194 | G50: =C50*Inputs!$B$35+D50*Inputs!$B$36+E50*Inputs!$B$37+F50*Inputs!$B$38 -> 2.8099217 | H50: =G50*Inputs!$B$40 -> 3.6809974 | I50: =MAX(-Inputs!$B$8,MIN(Inputs!$B$8,H50)) -> 3.6809974
A51: =Rules!A51 -> 48 | B51: =Rules!B51 -> 45937 | C51: =Rules!I51 -> 1.8374321 | D51: =Rules!M51 -> 1.6982562 | E51: =Rules!Q51 -> 4.3919228 | F51: =Rules!R51 -> 7.4378646 | G51: =C51*Inputs!$B$35+D51*Inputs!$B$36+E51*Inputs!$B$37+F51*Inputs!$B$38 -> 3.5367748 | H51: =G51*Inputs!$B$40 -> 4.633175 | I51: =MAX(-Inputs!$B$8,MIN(Inputs!$B$8,H51)) -> 4.633175
A52: =Rules!A52 -> 49 | B52: =Rules!B52 -> 45938 | C52: =Rules!I52 -> 1.9528764 | D52: =Rules!M52 -> 2.4948509 | E52: =Rules!Q52 -> 4.4214666 | F52: =Rules!R52 -> 9.8896752 | G52: =C52*Inputs!$B$35+D52*Inputs!$B$36+E52*Inputs!$B$37+F52*Inputs!$B$38 -> 4.1428964 | H52: =G52*Inputs!$B$40 -> 5.4271943 | I52: =MAX(-Inputs!$B$8,MIN(Inputs!$B$8,H52)) -> 5.4271943
A53: =Rules!A53 -> 50 | B53: =Rules!B53 -> 45939 | C53: =Rules!I53 -> 2.0454091 | D53: =Rules!M53 -> 2.9834633 | E53: =Rules!Q53 -> 4.417093 | F53: =Rules!R53 -> 7.0045752 | G53: =C53*Inputs!$B$35+D53*Inputs!$B$36+E53*Inputs!$B$37+F53*Inputs!$B$38 -> 3.8538869 | H53: =G53*Inputs!$B$40 -> 5.0485919 | I53: =MAX(-Inputs!$B$8,MIN(Inputs!$B$8,H53)) -> 5.0485919
A54: =Rules!A54 -> 51 | B54: =Rules!B54 -> 45940 | C54: =Rules!I54 -> 2.1140913 | D54: =Rules!M54 -> 3.1804976 | E54: =Rules!Q54 -> 4.4267105 | F54: =Rules!R54 -> 3.5578835 | G54: =C54*Inputs!$B$35+D54*Inputs!$B$36+E54*Inputs!$B$37+F54*Inputs!$B$38 -> 3.4066784 | H54: =G54*Inputs!$B$40 -> 4.4627487 | I54: =MAX(-Inputs!$B$8,MIN(Inputs!$B$8,H54)) -> 4.4627487
A55: =Rules!A55 -> 52 | B55: =Rules!B55 -> 45943 | C55: =Rules!I55 -> 2.1816767 | D55: =Rules!M55 -> 3.2359588 | E55: =Rules!Q55 -> 4.4829491 | F55: =Rules!R55 -> 1.4739223 | G55: =C55*Inputs!$B$35+D55*Inputs!$B$36+E55*Inputs!$B$37+F55*Inputs!$B$38 -> 3.1445294 | H55: =G55*Inputs!$B$40 -> 4.1193335 | I55: =MAX(-Inputs!$B$8,MIN(Inputs!$B$8,H55)) -> 4.1193335
A56: =Rules!A56 -> 53 | B56: =Rules!B56 -> 45944 | C56: =Rules!I56 -> 2.2278693 | D56: =Rules!M56 -> 3.4402133 | E56: =Rules!Q56 -> 4.4751483 | F56: =Rules!R56 -> 4.3846001 | G56: =C56*Inputs!$B$35+D56*Inputs!$B$36+E56*Inputs!$B$37+F56*Inputs!$B$38 -> 3.6410126 | H56: =G56*Inputs!$B$40 -> 4.7697265 | I56: =MAX(-Inputs!$B$8,MIN(Inputs!$B$8,H56)) -> 4.7697265
A57: =Rules!A57 -> 54 | B57: =Rules!B57 -> 45945 | C57: =Rules!I57 -> 2.3550563 | D57: =Rules!M57 -> 3.6891728 | E57: =Rules!Q57 -> 4.6108281 | F57: =Rules!R57 -> 3.6111405 | G57: =C57*Inputs!$B$35+D57*Inputs!$B$36+E57*Inputs!$B$37+F57*Inputs!$B$38 -> 3.6665182 | H57: =G57*Inputs!$B$40 -> 4.8031388 | I57: =MAX(-Inputs!$B$8,MIN(Inputs!$B$8,H57)) -> 4.8031388
A58: =Rules!A58 -> 55 | B58: =Rules!B58 -> 45946 | C58: =Rules!I58 -> 2.2438149 | D58: =Rules!M58 -> 4.2184901 | E58: =Rules!Q58 -> 4.1749326 | F58: =Rules!R58 -> 14.936591 | G58: =C58*Inputs!$B$35+D58*Inputs!$B$36+E58*Inputs!$B$37+F58*Inputs!$B$38 -> 5.3172913 | H58: =G58*Inputs!$B$40 -> 6.9656516 | I58: =MAX(-Inputs!$B$8,MIN(Inputs!$B$8,H58)) -> 6.9656516
A59: =Rules!A59 -> 56 | B59: =Rules!B59 -> 45947 | C59: =Rules!I59 -> 2.3648279 | D59: =Rules!M59 -> 4.7692463 | E59: =Rules!Q59 -> 4.1404145 | F59: =Rules!R59 -> 11.108432 | G59: =C59*Inputs!$B$35+D59*Inputs!$B$36+E59*Inputs!$B$37+F59*Inputs!$B$38 -> 4.8989285 | H59: =G59*Inputs!$B$40 -> 6.4175963 | I59: =MAX(-Inputs!$B$8,MIN(Inputs!$B$8,H59)) -> 6.4175963
A60: =Rules!A60 -> 57 | B60: =Rules!B60 -> 45950 | C60: =Rules!I60 -> 2.435682 | D60: =Rules!M60 -> 4.8757759 | E60: =Rules!Q60 -> 4.0945575 | F60: =Rules!R60 -> 5.9414003 | G60: =C60*Inputs!$B$35+D60*Inputs!$B$36+E60*Inputs!$B$37+F60*Inputs!$B$38 -> 4.1521696 | H60: =G60*Inputs!$B$40 -> 5.4393422 | I60: =MAX(-Inputs!$B$8,MIN(Inputs!$B$8,H60)) -> 5.4393422
... A183: =Rules!A183 -> 180 | B183: =Rules!B183 -> 46121 | C183: =Rules!I183 -> 17.859287 | D183: =Rules!M183 -> 20 | E183: =Rules!Q183 -> 4.0802013 | F183: =Rules!R183 -> 12.079885 | G183: =C183*Inputs!$B$35+D183*Inputs!$B$36+E183*Inputs!$B$37+F183*Inputs!$B$38 -> 12.704875 | H183: =G183*Inputs!$B$40 -> 16.643386 | I183: =MAX(-Inputs!$B$8,MIN(Inputs!$B$8,H183)) -> 16.643386

Sheet Position
A1: Position — forecast × vol scalar / 10
A3: Day | B3: Date | C3: Price | D3: Daily vol | E3: Combined fcst | F3: Block value | G3: Inst value vol | H3: Daily $ vol target | I3: Vol scalar | J3: Subsystem posn | K3: Rounded posn
A4: =Prices!A4 -> 1 | B4: =Prices!B4 -> 45870 | C4: =Prices!C4 -> 2400 | D4: =Prices!G4 -> 0 | E4: =Combine!I4 -> 0
A5: =Prices!A5 -> 2 | B5: =Prices!B5 -> 45873 | C5: =Prices!C5 -> 2399.42 | D5: =Prices!G5 -> 0 | E5: =Combine!I5 -> 0
A6: =Prices!A6 -> 3 | B6: =Prices!B6 -> 45874 | C6: =Prices!C6 -> 2398.15 | D6: =Prices!G6 -> 0 | E6: =Combine!I6 -> 0
A7: =Prices!A7 -> 4 | B7: =Prices!B7 -> 45875 | C7: =Prices!C7 -> 2398.36 | D7: =Prices!G7 -> 0 | E7: =Combine!I7 -> 0
A8: =Prices!A8 -> 5 | B8: =Prices!B8 -> 45876 | C8: =Prices!C8 -> 2418.07 | D8: =Prices!G8 -> 0 | E8: =Combine!I8 -> 0
A9: =Prices!A9 -> 6 | B9: =Prices!B9 -> 45877 | C9: =Prices!C9 -> 2417.89 | D9: =Prices!G9 -> 0 | E9: =Combine!I9 -> 0
A10: =Prices!A10 -> 7 | B10: =Prices!B10 -> 45880 | C10: =Prices!C10 -> 2384.59 | D10: =Prices!G10 -> 0 | E10: =Combine!I10 -> 0
A11: =Prices!A11 -> 8 | B11: =Prices!B11 -> 45881 | C11: =Prices!C11 -> 2395.37 | D11: =Prices!G11 -> 0 | E11: =Combine!I11 -> 0
A12: =Prices!A12 -> 9 | B12: =Prices!B12 -> 45882 | C12: =Prices!C12 -> 2391.85 | D12: =Prices!G12 -> 0 | E12: =Combine!I12 -> 0
A13: =Prices!A13 -> 10 | B13: =Prices!B13 -> 45883 | C13: =Prices!C13 -> 2389.53 | D13: =Prices!G13 -> 0 | E13: =Combine!I13 -> 0
A14: =Prices!A14 -> 11 | B14: =Prices!B14 -> 45884 | C14: =Prices!C14 -> 2395.16 | D14: =Prices!G14 -> 0.0055185884 | E14: =Combine!I14 -> 0
A15: =Prices!A15 -> 12 | B15: =Prices!B15 -> 45887 | C15: =Prices!C15 -> 2403.6 | D15: =Prices!G15 -> 0.0060988386 | E15: =Combine!I15 -> 0
... A48: =Prices!A48 -> 45 | B48: =Prices!B48 -> 45932 | C48: =Prices!C48 -> 2435.31 | D48: =Prices!G48 -> 0.0086730859 | E48: =Combine!I48 -> 0
A49: =Prices!A49 -> 46 | B49: =Prices!B49 -> 45933 | C49: =Prices!C49 -> 2453.78 | D49: =Prices!G49 -> 0.0087181471 | E49: =Combine!I49 -> 3.1184818 | F49: =C49*Inputs!$B$11*Inputs!$B$12*0.01 -> 2453.78 | G49: =C49*Inputs!$B$11*Inputs!$B$12*D49 -> 2139.2415 | H49: =Inputs!$B$4*Inputs!$B$5/SQRT(Inputs!$B$6) -> 12500 | I49: =H49/G49 -> 5.8431925 | J49: =I49*E49/Inputs!$B$7 -> 1.8221889 | K49: =ROUND(J49,0) -> 2
A50: =Prices!A50 -> 47 | B50: =Prices!B50 -> 45936 | C50: =Prices!C50 -> 2465.31 | D50: =Prices!G50 -> 0.0087065534 | E50: =Combine!I50 -> 3.6809974 | F50: =C50*Inputs!$B$11*Inputs!$B$12*0.01 -> 2465.31 | G50: =C50*Inputs!$B$11*Inputs!$B$12*D50 -> 2146.4353 | H50: =Inputs!$B$4*Inputs!$B$5/SQRT(Inputs!$B$6) -> 12500 | I50: =H50/G50 -> 5.823609 | J50: =I50*E50/Inputs!$B$7 -> 2.143669 | K50: =ROUND(J50,0) -> 2
A51: =Prices!A51 -> 48 | B51: =Prices!B51 -> 45937 | C51: =Prices!C51 -> 2484.29 | D51: =Prices!G51 -> 0.0085849768 | E51: =Combine!I51 -> 4.633175 | F51: =C51*Inputs!$B$11*Inputs!$B$12*0.01 -> 2484.29 | G51: =C51*Inputs!$B$11*Inputs!$B$12*D51 -> 2132.7572 | H51: =Inputs!$B$4*Inputs!$B$5/SQRT(Inputs!$B$6) -> 12500 | I51: =H51/G51 -> 5.8609578 | J51: =I51*E51/Inputs!$B$7 -> 2.7154843 | K51: =ROUND(J51,0) -> 3
A52: =Prices!A52 -> 49 | B52: =Prices!B52 -> 45938 | C52: =Prices!C52 -> 2499.16 | D52: =Prices!G52 -> 0.0085429529 | E52: =Combine!I52 -> 5.4271943 | F52: =C52*Inputs!$B$11*Inputs!$B$12*0.01 -> 2499.16 | G52: =C52*Inputs!$B$11*Inputs!$B$12*D52 -> 2135.0206 | H52: =Inputs!$B$4*Inputs!$B$5/SQRT(Inputs!$B$6) -> 12500 | I52: =H52/G52 -> 5.8547444 | J52: =I52*E52/Inputs!$B$7 -> 3.1774836 | K52: =ROUND(J52,0) -> 3
A53: =Prices!A53 -> 50 | B53: =Prices!B53 -> 45939 | C53: =Prices!C53 -> 2486.49 | D53: =Prices!G53 -> 0.0085629124 | E53: =Combine!I53 -> 5.0485919 | F53: =C53*Inputs!$B$11*Inputs!$B$12*0.01 -> 2486.49 | G53: =C53*Inputs!$B$11*Inputs!$B$12*D53 -> 2129.1596 | H53: =Inputs!$B$4*Inputs!$B$5/SQRT(Inputs!$B$6) -> 12500 | I53: =H53/G53 -> 5.870861 | J53: =I53*E53/Inputs!$B$7 -> 2.9639581 | K53: =ROUND(J53,0) -> 3
A54: =Prices!A54 -> 51 | B54: =Prices!B54 -> 45940 | C54: =Prices!C54 -> 2471.64 | D54: =Prices!G54 -> 0.0085518735 | E54: =Combine!I54 -> 4.4627487 | F54: =C54*Inputs!$B$11*Inputs!$B$12*0.01 -> 2471.64 | G54: =C54*Inputs!$B$11*Inputs!$B$12*D54 -> 2113.7153 | H54: =Inputs!$B$4*Inputs!$B$5/SQRT(Inputs!$B$6) -> 12500 | I54: =H54/G54 -> 5.9137577 | J54: =I54*E54/Inputs!$B$7 -> 2.6391615 | K54: =ROUND(J54,0) -> 3
A55: =Prices!A55 -> 52 | B55: =Prices!B55 -> 45943 | C55: =Prices!C55 -> 2462.99 | D55: =Prices!G55 -> 0.0084481456 | E55: =Combine!I55 -> 4.1193335 | F55: =C55*Inputs!$B$11*Inputs!$B$12*0.01 -> 2462.99 | G55: =C55*Inputs!$B$11*Inputs!$B$12*D55 -> 2080.7698 | H55: =Inputs!$B$4*Inputs!$B$5/SQRT(Inputs!$B$6) -> 12500 | I55: =H55/G55 -> 6.007392 | J55: =I55*E55/Inputs!$B$7 -> 2.4746451 | K55: =ROUND(J55,0) -> 2
A56: =Prices!A56 -> 53 | B56: =Prices!B56 -> 45944 | C56: =Prices!C56 -> 2478.24 | D56: =Prices!G56 -> 0.0084624693 | E56: =Combine!I56 -> 4.7697265 | F56: =C56*Inputs!$B$11*Inputs!$B$12*0.01 -> 2478.24 | G56: =C56*Inputs!$B$11*Inputs!$B$12*D56 -> 2097.203 | H56: =Inputs!$B$4*Inputs!$B$5/SQRT(Inputs!$B$6) -> 12500 | I56: =H56/G56 -> 5.9603196 | J56: =I56*E56/Inputs!$B$7 -> 2.8429094 | K56: =ROUND(J56,0) -> 3
A57: =Prices!A57 -> 54 | B57: =Prices!B57 -> 45945 | C57: =Prices!C57 -> 2475.02 | D57: =Prices!G57 -> 0.0082091798 | E57: =Combine!I57 -> 4.8031388 | F57: =C57*Inputs!$B$11*Inputs!$B$12*0.01 -> 2475.02 | G57: =C57*Inputs!$B$11*Inputs!$B$12*D57 -> 2031.7884 | H57: =Inputs!$B$4*Inputs!$B$5/SQRT(Inputs!$B$6) -> 12500 | I57: =H57/G57 -> 6.1522154 | J57: =I57*E57/Inputs!$B$7 -> 2.9549945 | K57: =ROUND(J57,0) -> 3
A58: =Prices!A58 -> 55 | B58: =Prices!B58 -> 45946 | C58: =Prices!C58 -> 2535.8 | D58: =Prices!G58 -> 0.0090572678 | E58: =Combine!I58 -> 6.9656516 | F58: =C58*Inputs!$B$11*Inputs!$B$12*0.01 -> 2535.8 | G58: =C58*Inputs!$B$11*Inputs!$B$12*D58 -> 2296.742 | H58: =Inputs!$B$4*Inputs!$B$5/SQRT(Inputs!$B$6) -> 12500 | I58: =H58/G58 -> 5.4424921 | J58: =I58*E58/Inputs!$B$7 -> 3.7910504 | K58: =ROUND(J58,0) -> 4
A59: =Prices!A59 -> 56 | B59: =Prices!B59 -> 45947 | C59: =Prices!C59 -> 2518.07 | D59: =Prices!G59 -> 0.0091193389 | E59: =Combine!I59 -> 6.4175963 | F59: =C59*Inputs!$B$11*Inputs!$B$12*0.01 -> 2518.07 | G59: =C59*Inputs!$B$11*Inputs!$B$12*D59 -> 2296.3134 | H59: =Inputs!$B$4*Inputs!$B$5/SQRT(Inputs!$B$6) -> 12500 | I59: =H59/G59 -> 5.4435079 | J59: =I59*E59/Inputs!$B$7 -> 3.4934236 | K59: =ROUND(J59,0) -> 3
A60: =Prices!A60 -> 57 | B60: =Prices!B60 -> 45950 | C60: =Prices!C60 -> 2493.42 | D60: =Prices!G60 -> 0.0092034809 | E60: =Combine!I60 -> 5.4393422 | F60: =C60*Inputs!$B$11*Inputs!$B$12*0.01 -> 2493.42 | G60: =C60*Inputs!$B$11*Inputs!$B$12*D60 -> 2294.8143 | H60: =Inputs!$B$4*Inputs!$B$5/SQRT(Inputs!$B$6) -> 12500 | I60: =H60/G60 -> 5.4470638 | J60: =I60*E60/Inputs!$B$7 -> 2.9628444 | K60: =ROUND(J60,0) -> 3
... A183: =Prices!A183 -> 180 | B183: =Prices!B183 -> 46121 | C183: =Prices!C183 -> 3127.97 | D183: =Prices!G183 -> 0.0087902773 | E183: =Combine!I183 -> 16.643386 | F183: =C183*Inputs!$B$11*Inputs!$B$12*0.01 -> 3127.97 | G183: =C183*Inputs!$B$11*Inputs!$B$12*D183 -> 2749.5724 | H183: =Inputs!$B$4*Inputs!$B$5/SQRT(Inputs!$B$6) -> 12500 | I183: =H183/G183 -> 4.5461615 | J183: =I183*E183/Inputs!$B$7 -> 7.5663522 | K183: =ROUND(J183,0) -> 8

Sheet Portfolio
A1: Portfolio — multi-instrument snapshot. Inst weight × IDM → position
A3: Portfolio capital | B3: 1000000
A4: Annual vol target | B4: 0.2
A5: Instrument Diversification Multiplier (IDM) | B5: 2.5
A6: Sum of instrument weights (sanity) | B6: =SUM(H9:H14) -> 0.8835
A8: Instrument | B8: Asset class | C8: Price | D8: Point size | E8: FX | F8: Ann vol | G8: Forecast | H8: Inst weight | I8: Inst value vol (daily $) | J8: Vol scalar | K8: Subsys posn | L8: Final posn (× wt × IDM)
A9: Gold | B9: Metals | C9: 2450 | D9: 100 | E9: 1 | F9: 0.15 | G9: 12.5 | H9: 0.1667 | I9: =C9*D9*E9*F9/SQRT(Inputs!$B$6) -> 2296.875 | J9: =($B$3*$B$4/SQRT(Inputs!$B$6))/I9 -> 5.4421769 | K9: =J9*G9/Inputs!$B$7 -> 6.8027211 | L9: =K9*H9*$B$5 -> 2.835034
A10: Crude WTI | B10: Energy | C10: 78 | D10: 1000 | E10: 1 | F10: 0.35 | G10: -8 | H10: 0.1667 | I10: =C10*D10*E10*F10/SQRT(Inputs!$B$6) -> 1706.25 | J10: =($B$3*$B$4/SQRT(Inputs!$B$6))/I10 -> 7.3260073 | K10: =J10*G10/Inputs!$B$7 -> -5.8608059 | L10: =K10*H10*$B$5 -> -2.4424908
A11: S&P 500 e-mini | B11: Equity | C11: 5250 | D11: 50 | E11: 1 | F11: 0.16 | G11: 6 | H11: 0.1667 | I11: =C11*D11*E11*F11/SQRT(Inputs!$B$6) -> 2625 | J11: =($B$3*$B$4/SQRT(Inputs!$B$6))/I11 -> 4.7619048 | K11: =J11*G11/Inputs!$B$7 -> 2.8571429 | L11: =K11*H11*$B$5 -> 1.1907143
A12: 10yr Note | B12: Rates | C12: 111.5 | D12: 1000 | E12: 1 | F12: 0.06 | G12: 15 | H12: 0.1667 | I12: =C12*D12*E12*F12/SQRT(Inputs!$B$6) -> 418.125 | J12: =($B$3*$B$4/SQRT(Inputs!$B$6))/I12 -> 29.895366 | K12: =J12*G12/Inputs!$B$7 -> 44.843049 | L12: =K12*H12*$B$5 -> 18.688341
A13: EUR/USD | B13: FX | C13: 1.08 | D13: 125000 | E13: 1 | F13: 0.08 | G13: -4 | H13: 0.05 | I13: =C13*D13*E13*F13/SQRT(Inputs!$B$6) -> 675 | J13: =($B$3*$B$4/SQRT(Inputs!$B$6))/I13 -> 18.518519 | K13: =J13*G13/Inputs!$B$7 -> -7.4074074 | L13: =K13*H13*$B$5 -> -0.92592593
A14: Corn | B14: Ags | C14: 4.35 | D14: 5000 | E14: 1 | F14: 0.22 | G14: 10.5 | H14: 0.1667 | I14: =C14*D14*E14*F14/SQRT(Inputs!$B$6) -> 299.0625 | J14: =($B$3*$B$4/SQRT(Inputs!$B$6))/I14 -> 41.797283 | K14: =J14*G14/Inputs!$B$7 -> 43.887147 | L14: =K14*H14*$B$5 -> 18.289969
A15: Totals / portfolio risk | I15: =SUMPRODUCT(ABS(L9:L14),C9:C14,D9:D14,E9:E14) -> 3804216.9 | J15: Gross $ notional
I16: =SQRT(SUMPRODUCT((L9:L14*I9:I14)^2)) -> 12685.009 | J16: Daily $ vol if zero-corr
I17: =$B$3*$B$4/SQRT(Inputs!$B$6) -> 12500 | J17: Target daily $ vol
A18: IDM is chosen so that when all forecasts are ±10 and correlations are realistic, realized portfolio vol ≈ target.

Sheet Discretionary
A1: Discretionary sizing — translate conviction into a Carver-style position
A3: Step 1 — Single trade sizing
A4: Instrument price | B4: 97.6
A5: Point size | B5: 1000
A6: FX to base currency | B6: 1
A7: Annualised % volatility of instrument | B7: 0.87
A8: Your conviction score (-10 … +10) | B8: 5
A9: Portfolio capital | B9: 250000
A10: Annual % vol target | B10: 12
A11: Business days | B11: 256
A13: Derived — single position
A14: Daily % vol | B14: =B7/SQRT(B11) -> 0.054375
A15: Instrument value vol (daily $) | B15: =B4*B5*B6*B14 -> 5307
A16: Daily $ vol target | B16: =B9*B10/SQRT(B11) -> 187500
A17: Vol scalar | B17: =B16/B15 -> 35.330695
A18: Position (contracts) at neutral forecast | B18: =B17 -> 35.330695
A19: Position at your conviction | B19: =B17*B8/10 -> 17.665348
A20: Rounded contracts | B20: =ROUND(B19,0) -> 18
